Workbook
Name DATA1: #REF!
Name _Key2: '[2]DK TRD'!#REF!
Name DATA13: #REF!
Name 层级: [3]筛选项!$B:$B
Name 职位名称列表: [4]筛选项!$A:$A
Name DATA1: #REF!
Name DATA13: #REF!
Name DATA1: #REF!
Name DATA13: #REF!

Sheet 业务情况
A1: Douyin weekly report Sales Performance（3.11-3.17）
B2: Date | C2: GMV | D2: Activity (h) | E2: Live room GMV | F2: Live room GMV/hour | G2: UV | H2: 短视频UV | I2: 短视频UV/UV | J2: Disc%（可删除） | K2: ATV | L2: CR% | M2: New Followers | N2: Return | O2: Return% | P2: 口碑分
B3: 44983 | C3: 73380.22 | D3: 16.5 | E3: 45660 | F3: 2767.27 | G3: 19999 | J3: 0.70352933 | K3: 543.55719 | L3: 0.00463 | M3: 77 | N3: 42889 | O3: =N3/C3 -> 0.58447631
B4: 44984 | C4: 85199 | D4: 17 | E4: 61198 | F4: =E4/D4 -> 3599.8824 | G4: 17755 | J4: 0.71 | K4: 665.61719 | L4: 0.00485 | M4: 113 | N4: 58698.9 | O4: =N4/C4 -> 0.68896231
B5: 44985 | C5: 56797 | D5: 17 | E5: 39498 | F5: =E5/D5 -> 2323.4118 | G5: 16942 | J5: 0.64361352 | K5: 397.18182 | L5: 0.00645 | M5: 102 | N5: 40803.5 | O5: =N5/C5 -> 0.71840942
B6: 44986 | C6: 207640.02 | D6: 17 | E6: 158005.71 | F6: =E6/D6 -> 9294.4535 | G6: 23542 | J6: 0.67001339 | K6: 598.38622 | L6: 0.0102 | M6: 223 | N6: 80786.75 | O6: =N6/C6 -> 0.38907119
B7: 44987 | C7: 182259.17 | D7: 17 | E7: 155976.19 | F7: =E7/D7 -> 9175.07 | G7: 26084 | J7: 0.67952639 | K7: 660.35931 | L7: 0.00825 | M7: 229 | N7: 89585.31 | O7: =N7/C7 -> 0.49152704
B8: 44988 | C8: 103773.21 | D8: 15.7 | E8: 73422.95 | F8: =E8/D8 -> 4676.621 | G8: 20450 | J8: 0.63150349 | K8: 356.1346 | L8: 0.00666 | M8: 184 | N8: 60058.06 | O8: =N8/C8 -> 0.5787434
B9: 44989 | C9: 99005.42 | D9: 11.5 | E9: 76249.77 | F9: =E9/D9 -> 6630.4148 | G9: 22937 | J9: 0.60282778 | K9: 392.69006 | L9: 0.0098 | M9: 236 | N9: 44304.48 | O9: =N9/C9 -> 0.4474955
B10: WK9- Actual TTL | C10: =C9+C8+C7+C6+C5+C4+C3 -> 808054.04 | D10: =SUM(D3:D9) -> 111.7 | E10: =SUM(E3:E9) -> 610010.62 | F10: =E10/D10 -> 5461.1515 | G10: =SUM(G3:G9) -> 147709 | J10: =AVERAGE(J3:J9) -> 0.66300198 | K10: =AVERAGE(K3:K9) -> 516.2752 | L10: =AVERAGE(L3:L9) -> 0.0072628571 | M10: =SUM(M3:M9) -> 1164 | N10: =SUM(N3:N9) -> 417126 | O10: =N10/C10 -> 0.51621052
A11: WK30 | B11: WK8- Actual TTL | C11: 672816 | D11: 110 | E11: 495309 | F11: 4502.8091 | G11: 1266046 | J11: 0.69754209 | K11: 547.70591 | L11: 0.0053571429 | M11: 1243 | N11: 403067.5 | O11: 0.59907538
B12: Weekly Target | C12: =SUM([1]运营日报!$G$97:$G$103) -> 1180000 | D12: =D3+D4+D5+D6+D7+D8+D9 -> 111.7 | E12: =C12*75% -> 885000
B13: Weekly Achv% | C13: =C10/C12 -> 0.68479156 | E13: =E10/E12 -> 0.68927754
A14: WK31 vs WK30 | B14: W-O-W G% | C14: =C10/C11-1 -> 0.20100301 | D14: =D10/D11-1 -> 0.015454545 | E14: =E10/E11-1 -> 0.23157588 | F14: =F10/F11-1 -> 0.21283212 | G14: =G10/G11-1 -> -0.88333046 | J14: =J10-J11 -> -0.034540103 | K14: =K10/K11-1 -> -0.057386105 | L14: =L10/L11-1 -> 0.35573333 | M14: =M10/M11-1 -> -0.063555913 | N14: =N10/N11-1 -> 0.034878773 | O14: =O10-O11 -> -0.082864854
B15: Feu. actual GMV | C15: 2674225.9
B16: MTD GMV target | C16: 3670000
B17: MTD Achv% | C17: =C15/C16 -> 0.7286719
B18: Feu. target GMV | C18: 3370000
B19: GMV Achv% | C19: =C15/C18 -> 0.79353884
B20: Feu actual Net Sales | C20: 1021958.4
B21: Feu target Net Sales | C21: 1685000
B22: Net Sales Achv% | C22: =C20/C21 -> 0.6065035
A25: 本周TOP10商品
A26: 销排 | B26: 短货号（可删除） | C26: 图片 | D26: 风格（可删除） | E26: 系列（可删除） | F26: 新老品 | G26: 成交件数 | H26: 成交金额 | I26: 件单价 | J26: 平折扣 | K26: 售罄率 | L26: 曝光点击率 | M26: 点击成交转化率 | N26: 退货率 | O26: 成交退款率
A27: 1 | B27: 823814 | C27: 82381460569 | D27: 户外 | E27: 健步2.1山地男鞋系列 | F27: 新品 | G27: 766 | H27: 1768007 | I27: 2308 | J27: 0.89 | K27: 0.7 | L27: 0.19 | M27: 0.0105 | N27: 0.39 | O27: 0.39
A28: 2 | B28: 824254 | C28: 82425451052 | D28: 户外 | E28: 奥途男鞋系列 | F28: 新品 | G28: 679 | H28: 1292271 | I28: 1903 | J28: 0.87 | K28: 0.62 | L28: 0.24 | M28: 0.0076 | N28: 0.44 | O28: 0.41
A29: 3 | B29: 524204 | C29: 52420402001 | D29: 休闲 | E29: 科摩男鞋系列 | F29: 231新品 | G29: 678 | H29: 1120088 | I29: 1652 | J29: 0.92 | K29: 0.99 | L29: 0.13 | M29: 0.0121 | N29: 0.45 | O29: 0.45
A30: 4 | B30: 520814 | C30: 52081401001 | D30: 休闲 | E30: 街头720男鞋系列 | F30: 新品 | G30: 583 | H30: 1080476 | I30: 1853 | J30: 0.77 | K30: 0.57 | L30: 0.12 | M30: 0.0161 | N30: 0.28 | O30: 0.28
A31: 5 | B31: 470484 | C31: 47048456787 | D31: 休闲 | E31: 柔酷7号男鞋系列 | F31: 231新品 | G31: 527 | H31: 760657 | I31: 1443 | J31: 0.8 | K31: 0.95 | L31: 0.16 | M31: 0.0139 | N31: 0.33 | O31: 0.33
A32: 6 | B32: 802864 | C32: 80286450869 | D32: 户外 | E32: 健步探索男鞋系列 | F32: 老品 | G32: 361 | H32: 501311 | I32: 1389 | J32: 0.5 | K32: 0.89 | L32: 0.07 | M32: 0.0095 | N32: 0.62 | O32: 0.52
A33: 7 | B33: 800424 | C33: 80042401001 | D33: 户外 | E33: 健步C男鞋系列 | F33: 新品 | G33: 143 | H33: 469192 | I33: 3281 | J33: 0.97 | K33: 0.46 | L33: 0.17 | M33: 0.0034 | N33: 0.45 | O33: 0.39
A34: 8 | B34: 822804 | C34: 82280460414 | D34: 户外 | E34: 健步2.1越野男鞋系列 | F34: 老品 | G34: 202 | H34: 371353 | I34: 1838 | J34: 0.77 | K34: 0.4 | L34: 0.14 | M34: 0.0164 | N34: 0.15 | O34: 0.15
A35: 9 | B35: 91504 | C35: 9150451707 | D35: 户外 | E35: 健步C男鞋系列 | F35: 新品 | G35: 113 | H35: 370491 | I35: 3279 | J35: 0.96 | K35: 0.25 | L35: 0.15 | M35: 0.0031 | N35: 0.48 | O35: 0.45
A36: 10 | B36: 207124 | C36: 20712401001 | D36: 正装 | E36: 雅仕系列 | F36: 新品 | G36: 225 | H36: 348770 | I36: 1550 | J36: 0.78 | K36: 0.38 | L36: 0.12 | M36: 0.0078 | N36: 0.42 | O36: 0.35
A39: 本周主播数据
A40: 主播名称 | B40: 大玉儿 | C40: 偲佟 | D40: 哈多 | E40: 王可 | F40: 白白 | G40: Anna
A41: 开播时长（小时数） | B41: 115 | C41: 106 | D41: 85 | E41: 69 | F41: 8 | G41: 30
A42: 直播间成交金额 | B42: 2030900 | C42: 820427 | D42: 783503 | E42: 523438 | F42: 81293 | G42: 347161
A43: 单小时成交金额 | B43: 17650 | C43: 7672 | D43: 9196 | E43: 7568 | F43: 10140 | G43: 11205
A44: 最高在线人数 | B44: 826 | C44: 631 | D44: 735 | E44: 97 | F44: 146 | G44: 92
...

Sheet 2026年-年度目标 
A1: 项目 | D1: 1月 | E1: 2月 | F1: 3月 | G1: 4月 | H1: 5月 | I1: 6月 | J1: 7月 | K1: 8月 | L1: 9月 | M1: 10月 | N1: 11月 | O1: 12月 | P1: MTD | Q1: TOTAL
A2: GXG | B2: 实际 | C2: GMV | D2: =SUMIF('GXG-日报'!$D:$D,D$1,'GXG-日报'!$F:$F) -> 18651172 | E2: =SUMIF('GXG-日报'!$D:$D,E$1,'GXG-日报'!$F:$F) -> 15084424 | F2: =SUMIF('GXG-日报'!$D:$D,F$1,'GXG-日报'!$F:$F) -> 2140928.6 | P2: =SUM(D2:F2) -> 35876525 | Q2: =SUM(D2:O2) -> 35876525
C3: NET | D3: =SUMIF('GXG-日报'!$D:$D,D$1,'GXG-日报'!$H:$H) -> 8286015.5 | E3: =SUMIF('GXG-日报'!$D:$D,E$1,'GXG-日报'!$H:$H) -> 5733417.1 | F3: =SUMIF('GXG-日报'!$D:$D,F$1,'GXG-日报'!$H:$H) -> 996198.25 | P3: =SUM(D3:F3) -> 15015631 | Q3: =SUM(D3:O3) -> 15015631
C4: 退货率 | D4: =1-D3/D2 -> 0.55573756 | E4: =1-E3/E2 -> 0.61991143 | F4: =1-F3/F2 -> 0.53468871 | P4: =1-P3/P2 -> 0.58146362 | Q4: =1-Q3/Q2 -> 0.58146362
C5: 商品卡GMV | D5: =SUMIF('GXG-日报'!$D:$D,D$1,'GXG-日报'!$I:$I) -> 2723069.9 | E5: =SUMIF('GXG-日报'!$D:$D,E$1,'GXG-日报'!$I:$I) -> 2451956.5 | F5: =SUMIF('GXG-日报'!$D:$D,F$1,'GXG-日报'!$I:$I) -> 261475.9 | P5: =SUM(D5:F5) -> 5436502.3 | Q5: =SUM(D5:O5) -> 5436502.3
C6: 商品卡占比 | D6: =D5/D2 -> 0.14599993 | E6: =E5/E2 -> 0.1625489 | F6: =F5/F2 -> 0.122132 | P6: =P5/P2 -> 0.15153369 | Q6: =Q5/Q2 -> 0.15153369
C7: 投放消耗金额 | D7: =SUMIF('GXG-日报'!$D:$D,D$1,'GXG-日报'!$K:$K) -> 549643.94 | E7: =SUMIF('GXG-日报'!$D:$D,E$1,'GXG-日报'!$K:$K) -> 400283.8 | F7: =SUMIF('GXG-日报'!$D:$D,F$1,'GXG-日报'!$K:$K) -> 63607.54 | P7: =SUM(D7:F7) -> 1013535.3 | Q7: =SUM(D7:O7) -> 1013535.3
C8: 投放费比 | D8: =D7/D3 -> 0.066333926 | E8: =E7/E3 -> 0.069815922 | F8: =F7/F3 -> 0.063850283 | P8: =P7/P3 -> 0.067498681 | Q8: =Q7/Q3 -> 0.067498681
B9: 目标 | C9: GMV | D9: 15000000 | E9: 9000000 | F9: 4600000 | G9: 5400000 | H9: 6500000 | I9: 6500000 | J9: 6000000 | K9: 6500000 | L9: 7000000 | M9: 12000000 | N9: 16000000 | O9: 15000000 | P9: =SUM(D9:F9) -> 28600000 | Q9: =SUM(D9:O9) -> 109500000
C10: NET | D10: 6750000 | E10: 3870000 | F10: 2162000 | G10: 2808000 | H10: 3380000 | I10: 3380000 | J10: 3120000 | K10: 3250000 | L10: 3500000 | M10: 5400000 | N10: 6400000 | O10: 6000000 | P10: =SUM(D10:F10) -> 12782000 | Q10: =SUM(D10:O10) -> 50020000
C11: 退货率 | D11: =1-D10/D9 -> 0.55 | E11: =1-E10/E9 -> 0.57 | F11: =1-F10/F9 -> 0.53 | G11: =1-G10/G9 -> 0.48 | H11: =1-H10/H9 -> 0.48 | I11: =1-I10/I9 -> 0.48 | J11: =1-J10/J9 -> 0.48 | K11: =1-K10/K9 -> 0.5 | ... Q11: =1-Q10/Q9 -> 0.54319635
C12: 投放费比 | D12: 0.06 | E12: 0.06 | F12: 0.06 | G12: 0.06 | H12: 0.06 | I12: 0.06 | J12: 0.06 | K12: 0.06 | L12: 0.06 | M12: 0.06 | N12: 0.06 | O12: 0.06 | P12: 0.06 | Q12: 0.06
B13: 目标达成率 | C13: GMV | D13: =D2/D9 -> 1.2434115 | E13: =E2/E9 -> 1.6760471 | F13: =F2/F9 -> 0.46541926 | G13: =G2/G9 -> 0 | H13: =H2/H9 -> 0 | I13: =I2/I9 -> 0 | J13: =J2/J9 -> 0 | K13: =K2/K9 -> 0 | ... Q13: =Q2/Q9 -> 0.3276395
C14: NET | D14: =D3/D10 -> 1.2275578 | E14: =E3/E10 -> 1.4815031 | F14: =F3/F10 -> 0.46077625 | G14: =G3/G10 -> 0 | H14: =H3/H10 -> 0 | I14: =I3/I10 -> 0 | J14: =J3/J10 -> 0 | K14: =K3/K10 -> 0 | ... Q14: =Q3/Q10 -> 0.30019254
C15: 退货率 | D15: =D4/D11 -> 1.0104319 | E15: =E4/E11 -> 1.0875639 | F15: =F4/F11 -> 1.0088466 | G15: =G4/G11 -> 0 | H15: =H4/H11 -> 0 | I15: =I4/I11 -> 0 | J15: =J4/J11 -> 0 | K15: =K4/K11 -> 0 | ... Q15: =Q4/Q11 -> 1.0704483
C16: 投放费比 | D16: =D8/D12 -> 1.1055654 | E16: =E8/E12 -> 1.1635987 | F16: =F8/F12 -> 1.0641714 | G16: =G8/G12 -> 0 | H16: =H8/H12 -> 0 | I16: =I8/I12 -> 0 | J16: =J8/J12 -> 0 | K16: =K8/K12 -> 0 | ... Q16: =Q8/Q12 -> 1.124978
B17: YOY | C17: GMV | D17: =D2/D80-1 -> 0.2404478 | E17: =E2/E80-1 -> 1.4696094 | F17: =F2/F80-1 -> -0.66698759 | G17: =G2/G80-1 -> -1 | H17: =H2/H80-1 -> -1 | I17: =I2/I80-1 -> -1 | J17: =J2/J80-1 -> -1 | K17: =K2/K80-1 -> -1 | ... Q17: =Q2/Q80-1 -> -0.64429276
C18: NET | D18: =D3/D81-1 -> 0.17629221 | E18: =E3/E81-1 -> 0.81603907 | F18: =F3/F81-1 -> -0.69731347 | G18: =G3/G81-1 -> -1 | H18: =H3/H81-1 -> -1 | I18: =I3/I81-1 -> -1 | J18: =J3/J81-1 -> -1 | K18: =K3/K81-1 -> -1 | ... Q18: =Q3/Q81-1 -> -0.70163201
C19: 退货率 | D19: =D4-D82 -> 0.024230305 | E19: =E4-E82 -> 0.13678924 | F19: =F4-F82 -> 0.046619096 | G19: =G4-G82 -> -0.36143145 | H19: =H4-H82 -> -0.43705456 | I19: =I4-I82 -> -0.36090667 | J19: =J4-J82 -> -0.35611135 | K19: =K4-K82 -> -0.48703971 | ... Q19: =Q4-Q82 -> 0.080432769
A20: DAZZLE 抖音 | B20: 实际 | C20: GMV | D20: =SUMIF('DAZZLE-日报'!$D:$D,D$1,'DAZZLE-日报'!$F:$F) -> 22583187 | E20: =SUMIF('DAZZLE-日报'!$D:$D,E$1,'DAZZLE-日报'!$F:$F) -> 15289696 | F20: =SUMIF('DAZZLE-日报'!$D:$D,F$1,'DAZZLE-日报'!$F:$F) -> 4755169 | P20: =SUM(D20:F20) -> 42628052 | Q20: =SUM(D20:O20) -> 42628052
C21: NET | D21: =SUMIF('DAZZLE-日报'!$D:$D,D$1,'DAZZLE-日报'!$H:$H) -> 3027474.2 | E21: =SUMIF('DAZZLE-日报'!$D:$D,E$1,'DAZZLE-日报'!$H:$H) -> 2171222.5 | F21: =SUMIF('DAZZLE-日报'!$D:$D,F$1,'DAZZLE-日报'!$H:$H) -> 726221.35 | P21: =SUM(D21:F21) -> 5924918.2 | Q21: =SUM(D21:O21) -> 5924918.2
C22: 退货率 | D22: =1-D21/D20 -> 0.86594123 | E22: =1-E21/E20 -> 0.85799439 | F22: =1-F21/F20 -> 0.84727749 | P22: =1-P21/P20 -> 0.86100894 | Q22: =1-Q21/Q20 -> 0.86100894
C23: 商品卡GMV | D23: =SUMIF('DAZZLE-日报'!$D:$D,D$1,'DAZZLE-日报'!$I:$I) -> 6885434.3 | E23: =SUMIF('DAZZLE-日报'!$D:$D,E$1,'DAZZLE-日报'!$I:$I) -> 5390649.5 | F23: =SUMIF('DAZZLE-日报'!$D:$D,F$1,'DAZZLE-日报'!$I:$I) -> 1824750.8 | P23: =SUM(D23:F23) -> 14100835 | Q23: =SUM(D23:O23) -> 14100835
C24: 商品卡占比 | D24: =D23/D20 -> 0.30489205 | E24: =E23/E20 -> 0.35256748 | F24: =F23/F20 -> 0.38374048 | P24: =P23/P20 -> 0.33078769 | Q24: =Q23/Q20 -> 0.33078769
C25: 投放消耗金额 | D25: =SUMIF('DAZZLE-日报'!$D:$D,D$1,'DAZZLE-日报'!$K:$K) -> 72623.55 | E25: =SUMIF('DAZZLE-日报'!$D:$D,E$1,'DAZZLE-日报'!$K:$K) -> 45510.23 | F25: =SUMIF('DAZZLE-日报'!$D:$D,F$1,'DAZZLE-日报'!$K:$K) -> 12451.32 | P25: =SUM(D25:F25) -> 130585.1 | Q25: =SUM(D25:O25) -> 130585.1
C26: 投放费比 | D26: =D25/D21 -> 0.023988164 | E26: =E25/E21 -> 0.020960647 | F26: =F25/F21 -> 0.017145351 | P26: =P25/P21 -> 0.022039984 | Q26: =Q25/Q21 -> 0.022039984
B27: 目标 | C27: GMV | D27: 18860000 | E27: 11527500 | F27: 17240000 | G27: 13590882 | H27: 16215000 | I27: 18470333 | J27: 15457500 | K27: 12551667 | L27: 13434294 | M27: 17610882 | N27: 21693000 | O27: 20075677 | P27: =SUM(D27:F27) -> 47627500 | Q27: =SUM(D27:O27) -> 196726735
C28: NET | D28: 3041200 | E28: 1773800 | F28: 3033600 | G28: 2211000 | H28: 2602600 | I28: 2687800 | J28: 2477400 | K28: 2000600 | L28: 2258190 | M28: 2784150 | N28: 3051370 | O28: 3089940 | P28: =SUM(D28:F28) -> 7848600 | Q28: =SUM(D28:O28) -> 31011650
C29: 退货率 | D29: =1-D28/D27 -> 0.83874867 | E29: =1-E28/E27 -> 0.84612448 | F29: =1-F28/F27 -> 0.82403712 | G29: =1-G28/G27 -> 0.8373174 | H29: =1-H28/H27 -> 0.8394943 | I29: =1-I28/I27 -> 0.85448015 | J29: =1-J28/J27 -> 0.83972829 | K29: =1-K28/K27 -> 0.84061081 | ... Q29: =1-Q28/Q27 -> 0.84236179
C30: 投放费比 | D30: 0.03 | E30: 0.03 | F30: 0.03 | G30: 0.03 | H30: 0.03 | I30: 0.03 | J30: 0.03 | K30: 0.03 | L30: 0.03 | M30: 0.03 | N30: 0.03 | O30: 0.03 | P30: 0.03 | Q30: 0.03
B31: 目标达成率 | C31: GMV | D31: =D20/D27 -> 1.1974118 | E31: =E20/E27 -> 1.326367 | F31: =F20/F27 -> 0.27582187 | P31: =P20/P27 -> 0.89503022 | Q31: =Q20/Q27 -> 0.21668662
C32: NET | D32: =D21/D28 -> 0.99548673 | E32: =E21/E28 -> 1.2240515 | F32: =F21/F28 -> 0.23939259 | P32: =P21/P28 -> 0.75490128 | Q32: =Q21/Q28 -> 0.19105459
C33: 退货率 | D33: =D22/D29 -> 1.0324204 | E33: =E22/E29 -> 1.0140286 | F33: =F22/F29 -> 1.0282031 | P33: =P22/P29 -> 1.0308908 | Q33: =Q22/Q29 -> 1.0221367
C34: 投放费比 | D34: =D26/D30 -> 0.79960548 | E34: =E26/E30 -> 0.69868824 | F34: =F26/F30 -> 0.5715117 | P34: =P26/P30 -> 0.73466613 | Q34: =Q26/Q30 -> 0.73466613
B35: YOY | C35: GMV | D35: =D20/D84-1 -> 0.60324565 | E35: =E20/E84-1 -> 0.31297102 | F35: =F20/F84-1 -> -0.64868726 | G35: =G20/G84-1 -> -1 | H35: =H20/H84-1 -> -1 | I35: =I20/I84-1 -> -1 | J35: =J20/J84-1 -> -1 | K35: =K20/K84-1 -> -1 | ... Q35: =Q20/Q84-1 -> -0.78773921
C36: NET | D36: =D21/D85-1 -> 0.29591477 | E36: =E21/E85-1 -> 0.018429408 | F36: =F21/F85-1 -> -0.52468008 | G36: =G28/G85-1 -> -0.027179445 | H36: =H28/H85-1 -> -0.22268192 | I36: =I28/I85-1 -> 0.39115719 | J36: =J28/J85-1 -> 0.66472167 | K36: =K28/K85-1 -> 0.10484705 | L36: =L28/L85-1 -> -0.038380548 | M36: =M28/M85-1 -> -0.23660685 | N36: =N28/N85-1 -> 0.70037433 | O36: =O28/O85-1 -> -0.26475843 | P36: =P21/P85-1 -> 0.32604868 | Q36: =Q21/Q85-1 -> -0.79456211
C37: 退货率 | D37: =D22-D86 -> 0.031792522 | E37: =E22-E86 -> 0.041069671 | F37: =F22-F86 -> -0.039844085 | G37: =G22-G86 -> -0.79616059 | H37: =H22-H86 -> -0.84782612 | I37: =I22-I86 -> -0.88915968 | J37: =J22-J86 -> -0.90604028 | K37: =K22-K86 -> -0.83512547 | ... Q37: =Q22-Q86 -> 0.0046160984
A38: DAZZLE 视频号 | B38: 实际 | C38: GMV | D38: =SUMIF('DAZZLE（视频号）-日报'!$D:$D,D$1,'DAZZLE（视频号）-日报'!$F:$F) -> 1667428 | E38: =SUMIF('DAZZLE（视频号）-日报'!$D:$D,E$1,'DAZZLE（视频号）-日报'!$F:$F) -> 1281220 | P38: =SUM(D38:F38) -> 2948648 | Q38: =SUM(D38:O38) -> 2948648
C39: NET | D39: =SUMIF('DAZZLE（视频号）-日报'!$D:$D,D$1,'DAZZLE（视频号）-日报'!$G:$G) -> 210107.6 | E39: =SUMIF('DAZZLE（视频号）-日报'!$D:$D,E$1,'DAZZLE（视频号）-日报'!$G:$G) -> 347192.51 | P39: =SUM(D39:F39) -> 557300.11 | Q39: =SUM(D39:O39) -> 557300.11
C40: 退货率 | D40: =1-D39/D38 -> 0.873993 | E40: =1-E39/E38 -> 0.72901413 | P40: =1-P39/P38 -> 0.81099809 | Q40: =1-Q39/Q38 -> 0.81099809
...

Sheet 2026年-周目标
A1: 品牌 | D1: 1.1-1.4 | E1: 1.5-1.11 | F1: 1.12-1.18 | G1: 1.19-1.25 | H1: 1.26-2.1 | I1: 2.2-2.8 | J1: 2.9-2.15 | K1: 2.16-2.22 | L1: 2.23-3.1 | M1: 3.2-3.8 | N1: 周环比 | O1: 达成/未达成原因 | P1: 后期措施 | Q1: W10重点工作&成果 | S1: W11重点工作安排
D2: W1 | E2: W2 | F2: W3 | G2: W4 | H2: W5 | I2: W6 | J2: W7 | K2: W8 | L2: W9 | M2: W10
A3: GXG | B3: 实际 | C3: GMV | D3: =SUMIF('GXG-日报'!$E:$E,D$2,'GXG-日报'!$F:$F) -> 2454809.4 | E3: =SUMIF('GXG-日报'!$E:$E,E$2,'GXG-日报'!$F:$F) -> 4472122.1 | F3: =SUMIF('GXG-日报'!$E:$E,F$2,'GXG-日报'!$F:$F) -> 2967577.7 | G3: =SUMIF('GXG-日报'!$E:$E,G$2,'GXG-日报'!$F:$F) -> 4606145.8 | H3: =SUMIF('GXG-日报'!$E:$E,H$2,'GXG-日报'!$F:$F) -> 4816637.9 | I3: =SUMIF('GXG-日报'!$E:$E,I$2,'GXG-日报'!$F:$F) -> 8272352 | J3: =SUMIF('GXG-日报'!$E:$E,J$2,'GXG-日报'!$F:$F) -> 4130552.9 | K3: =SUMIF('GXG-日报'!$E:$E,K$2,'GXG-日报'!$F:$F) -> 331005.2 | ... M3: =SUMIF('GXG-日报'!$E:$E,M$2,'GXG-日报'!$F:$F) -> 1914906.3 | N3: =M3/L3-1 -> 0.0023505354 | O3: 1、本周主播千喜临时调休4天，任真休假，主播以可可、周周、双胞胎为主，其中可可打款皮衣效能较好2W；周末任真、千喜回归，打款西装效能较好 | Q3: 1 | R3: 3.6平台&品牌会议报告完成 | S3: 1 | T3: 先锋大赛交稿
C4: NET | D4: =SUMIF('GXG-日报'!$E:$E,D$2,'GXG-日报'!$H:$H) -> 1136394.9 | E4: =SUMIF('GXG-日报'!$E:$E,E$2,'GXG-日报'!$H:$H) -> 1962965.2 | F4: =SUMIF('GXG-日报'!$E:$E,F$2,'GXG-日报'!$H:$H) -> 884420.8 | G4: =SUMIF('GXG-日报'!$E:$E,G$2,'GXG-日报'!$H:$H) -> 2449130.4 | H4: =SUMIF('GXG-日报'!$E:$E,H$2,'GXG-日报'!$H:$H) -> 2081978.3 | I4: =SUMIF('GXG-日报'!$E:$E,I$2,'GXG-日报'!$H:$H) -> 3898600.9 | J4: =SUMIF('GXG-日报'!$E:$E,J$2,'GXG-日报'!$H:$H) -> 961150.59 | K4: =SUMIF('GXG-日报'!$E:$E,K$2,'GXG-日报'!$H:$H) -> -157222.28 | ... M4: =SUMIF('GXG-日报'!$E:$E,M$2,'GXG-日报'!$H:$H) -> 904305.73 | N4: =M4/L4-1 -> 0.011633714 | Q4: 2 | S4: 2 | T4: 26年春季3-4月打款计划全盘
C5: 退货率 | D5: =1-D4/D3 -> 0.53707407 | E5: =1-E4/E3 -> 0.56106629 | F5: =1-F4/F3 -> 0.70197215 | G5: =1-G4/G3 -> 0.46829073 | H5: =1-H4/H3 -> 0.5677528 | I5: =1-I4/I3 -> 0.52871917 | J5: =1-J4/J3 -> 0.76730704 | K5: =1-K4/K3 -> 1.4749843 | ... M5: =1-M4/M3 -> 0.52775458 | N5: =M5/L5-1 -> -0.0081443723 | Q5: 3 | S5: 3 | T5: 商品卡全盘
C6: 商品卡GMV | D6: =SUMIF('GXG-日报'!$E:$E,D$2,'GXG-日报'!$I:$I) -> 249797.42 | E6: =SUMIF('GXG-日报'!$E:$E,E$2,'GXG-日报'!$I:$I) -> 419091.35 | F6: =SUMIF('GXG-日报'!$E:$E,F$2,'GXG-日报'!$I:$I) -> 475345.5 | G6: =SUMIF('GXG-日报'!$E:$E,G$2,'GXG-日报'!$I:$I) -> 766161.6 | H6: =SUMIF('GXG-日报'!$E:$E,H$2,'GXG-日报'!$I:$I) -> 984376.4 | I6: =SUMIF('GXG-日报'!$E:$E,I$2,'GXG-日报'!$I:$I) -> 1423772.5 | J6: =SUMIF('GXG-日报'!$E:$E,J$2,'GXG-日报'!$I:$I) -> 614786.3 | K6: =SUMIF('GXG-日报'!$E:$E,K$2,'GXG-日报'!$I:$I) -> 74016.2 | ... M6: =SUMIF('GXG-日报'!$E:$E,M$2,'GXG-日报'!$I:$I) -> 240644.6 | N6: =M6/L6-1 -> 0.27655875 | Q6: 4 | S6: 4 | T6: 26年秋季款下单计划盘点
C7: 商品卡占比 | D7: =D6/D3 -> 0.10175838 | E7: =E6/E3 -> 0.093711965 | F7: =F6/F3 -> 0.16017963 | G7: =G6/G3 -> 0.16633464 | H7: =H6/H3 -> 0.20437002 | I7: =I6/I3 -> 0.17211218 | J7: =J6/J3 -> 0.14883874 | K7: =K6/K3 -> 0.22361038 | ... M7: =M6/M3 -> 0.12566913 | N7: =M7/L7-1 -> 0.27356519 | Q7: 5 | S7: 5
C8: 投放消耗金额 | D8: =SUMIF('GXG-日报'!$E:$E,D$2,'GXG-日报'!$K:$K) -> 81402.31 | E8: =SUMIF('GXG-日报'!$E:$E,E$2,'GXG-日报'!$K:$K) -> 145657.56 | F8: =SUMIF('GXG-日报'!$E:$E,F$2,'GXG-日报'!$K:$K) -> 80162.01 | G8: =SUMIF('GXG-日报'!$E:$E,G$2,'GXG-日报'!$K:$K) -> 127649.27 | H8: =SUMIF('GXG-日报'!$E:$E,H$2,'GXG-日报'!$K:$K) -> 130671.33 | I8: =SUMIF('GXG-日报'!$E:$E,I$2,'GXG-日报'!$K:$K) -> 219375.53 | J8: =SUMIF('GXG-日报'!$E:$E,J$2,'GXG-日报'!$K:$K) -> 108471.95 | K8: =SUMIF('GXG-日报'!$E:$E,K$2,'GXG-日报'!$K:$K) -> 7787.9 | ... M8: =SUMIF('GXG-日报'!$E:$E,M$2,'GXG-日报'!$K:$K) -> 56373.81 | N8: =M8/L8-1 -> 0.0069698971 | Q8: 6 | S8: 6
C9: 投放费比 | D9: =D8/D4 -> 0.07163206 | E9: =E8/E4 -> 0.074202824 | F9: =F8/F4 -> 0.090637862 | G9: =G8/G4 -> 0.052120242 | H9: =H8/H4 -> 0.062763062 | I9: =I8/I4 -> 0.056270322 | J9: =J8/J4 -> 0.11285635 | K9: =K8/K4 -> -0.049534328 | ... M9: =M8/M4 -> 0.062339326 | N9: =M9/L9-1 -> -0.0046101834 | Q9: 7 | S9: 7
B10: 目标 | C10: GMV | D10: 2000000 | E10: 3500000 | F10: 3500000 | G10: 3500000 | H10: 3500000 | I10: 3500000 | J10: 3500000 | K10: 3500000 | L10: 3500000 | M10: 2000000 | N10: =M10/L10-1 -> -0.42857143 | Q10: 8 | S10: 8
C11: NET | D11: =D10*(1-55%) -> 900000 | E11: =E10*(1-55%) -> 1575000 | F11: =F10*(1-55%) -> 1575000 | G11: =G10*(1-55%) -> 1575000 | H11: =H10*(1-55%) -> 1575000 | I11: =I10*(1-55%) -> 1575000 | J11: =J10*(1-55%) -> 1575000 | K11: =K10*(1-55%) -> 1575000 | ... M11: =M10*(1-55%) -> 900000 | N11: =M11/L11-1 -> -0.42857143 | Q11: 9 | S11: 9
C12: 退货率 | D12: =1-D11/D10 -> 0.55 | E12: =1-E11/E10 -> 0.55 | F12: =1-F11/F10 -> 0.55 | G12: =1-G11/G10 -> 0.55 | H12: =1-H11/H10 -> 0.55 | I12: =1-I11/I10 -> 0.55 | J12: =1-J11/J10 -> 0.55 | K12: =1-K11/K10 -> 0.55 | ... M12: =1-M11/M10 -> 0.55 | N12: =M12/L12-1 -> 0 | Q12: 10 | S12: 10
C13: 投放费比 | D13: 0.05 | E13: 0.05 | F13: 0.05 | G13: 0.05 | H13: 0.05 | I13: 0.05 | J13: 0.05 | K13: 0.05 | L13: 0.05 | M13: 0.05 | N13: =M13/L13-1 -> 0 | Q13: 11 | S13: 11
B14: 目标达成率 | C14: GMV | D14: =D3/D10 -> 1.2274047 | E14: =E3/E10 -> 1.2777492 | F14: =F3/F10 -> 0.84787934 | G14: =G3/G10 -> 1.3160417 | H14: =H3/H10 -> 1.3761823 | I14: =I3/I10 -> 2.3635291 | J14: =J3/J10 -> 1.180158 | K14: =K3/K10 -> 0.094572914 | ... M14: =M3/M10 -> 0.95745315 | N14: =M14/L14-1 -> 0.75411344 | Q14: 12 | S14: 12
C15: NET | D15: =D4/D11 -> 1.262661 | E15: =E4/E11 -> 1.2463271 | F15: =F4/F11 -> 0.56153702 | G15: =G4/G11 -> 1.5550034 | H15: =H4/H11 -> 1.321891 | I15: =I4/I11 -> 2.4753022 | J15: =J4/J11 -> 0.61025434 | K15: =K4/K11 -> -0.09982367 | ... M15: =M4/M11 -> 1.0047841 | N15: =M15/L15-1 -> 0.770359 | Q15: 13 | S15: 13
C16: 退货率 | D16: =D5/D12 -> 0.9764983 | E16: =E5/E12 -> 1.0201205 | F16: =F5/F12 -> 1.276313 | G16: =G5/G12 -> 0.85143769 | H16: =H5/H12 -> 1.0322778 | I16: =I5/I12 -> 0.96130758 | J16: =J5/J12 -> 1.3951037 | K16: =K5/K12 -> 2.6817897 | ... M16: =M5/M12 -> 0.95955378 | N16: =M16/L16-1 -> -0.0081443723 | Q16: 14 | S16: 14
C17: 投放费比 | D17: =D9/D13 -> 1.4326412 | E17: =E9/E13 -> 1.4840565 | F17: =F9/F13 -> 1.8127572 | G17: =G9/G13 -> 1.0424048 | H17: =H9/H13 -> 1.2552612 | I17: =I9/I13 -> 1.1254064 | J17: =J9/J13 -> 2.2571271 | K17: =K9/K13 -> -0.99068656 | ... M17: =M9/M13 -> 1.2467865 | N17: =M17/L17-1 -> -0.0046101834 | Q17: 15 | S17: 15
A18: 品牌 | D18: W1 | E18: W2 | F18: W3 | G18: W4 | H18: W5 | I18: W6 | J18: W7 | K18: W8 | L18: W9 | M18: W10 | N18: 周环比 | O18: 达成/未达成原因 | P18: 后期措施 | Q18: W10重点工作&成果 | S18: W11重点工作安排
A19: DAZZLE 抖音 | B19: 实际 | C19: GMV | D19: =SUMIF('DAZZLE-日报'!$E:$E,D$18,'DAZZLE-日报'!$F:$F) -> 2304116 | E19: =SUMIF('DAZZLE-日报'!$E:$E,E$18,'DAZZLE-日报'!$F:$F) -> 4544258 | F19: =SUMIF('DAZZLE-日报'!$E:$E,F$18,'DAZZLE-日报'!$F:$F) -> 5227052 | G19: =SUMIF('DAZZLE-日报'!$E:$E,G$18,'DAZZLE-日报'!$F:$F) -> 5660742.6 | H19: =SUMIF('DAZZLE-日报'!$E:$E,H$18,'DAZZLE-日报'!$F:$F) -> 5716888.5 | I19: =SUMIF('DAZZLE-日报'!$E:$E,I$18,'DAZZLE-日报'!$F:$F) -> 5612308.4 | J19: =SUMIF('DAZZLE-日报'!$E:$E,J$18,'DAZZLE-日报'!$F:$F) -> 4373896.6 | K19: =SUMIF('DAZZLE-日报'!$E:$E,K$18,'DAZZLE-日报'!$F:$F) -> 1286931.7 | ... M19: =SUMIF('DAZZLE-日报'!$E:$E,M$18,'DAZZLE-日报'!$F:$F) -> 4198718.8 | N19: =M19/L19-1 -> 0.13382691 | Q19: 1 | R19: 4月内容场跟进 | S19: 1 | T19: 先锋大赛交稿
C20: NET | D20: =SUMIF('DAZZLE-日报'!$E:$E,D$18,'DAZZLE-日报'!$H:$H) -> -12713.3 | E20: =SUMIF('DAZZLE-日报'!$E:$E,E$18,'DAZZLE-日报'!$H:$H) -> 834747.6 | F20: =SUMIF('DAZZLE-日报'!$E:$E,F$18,'DAZZLE-日报'!$H:$H) -> 1003570.1 | G20: =SUMIF('DAZZLE-日报'!$E:$E,G$18,'DAZZLE-日报'!$H:$H) -> 462810.78 | H20: =SUMIF('DAZZLE-日报'!$E:$E,H$18,'DAZZLE-日报'!$H:$H) -> 889985.41 | I20: =SUMIF('DAZZLE-日报'!$E:$E,I$18,'DAZZLE-日报'!$H:$H) -> 770013.94 | J20: =SUMIF('DAZZLE-日报'!$E:$E,J$18,'DAZZLE-日报'!$H:$H) -> 616238.78 | K20: =SUMIF('DAZZLE-日报'!$E:$E,K$18,'DAZZLE-日报'!$H:$H) -> 705347.45 | ... M20: =SUMIF('DAZZLE-日报'!$E:$E,M$18,'DAZZLE-日报'!$H:$H) -> 538936.23 | N20: =M20/L20-1 -> 3.6467555 | Q20: 2 | R20: 主播灿灿沟通协商 | S20: 2 | T20: 秋冬订货资料梳理跟进
C21: 退货率 | D21: =1-D20/D19 -> 1.0055176 | E21: =1-E20/E19 -> 0.81630717 | F21: =1-F20/F19 -> 0.80800458 | G21: =1-G20/G19 -> 0.91824204 | H21: =1-H20/H19 -> 0.84432346 | I21: =1-I20/I19 -> 0.86279907 | J21: =1-J20/J19 -> 0.85910989 | K21: =1-K20/K19 -> 0.45191538 | ... M21: =1-M20/M19 -> 0.8716427 | N21: =M21/L21-1 -> -0.10017506 | Q21: 3 | S21: 3 | T21: 主播小鱼沟通协商
C22: 商品卡GMV | D22: =SUMIF('DAZZLE-日报'!$E:$E,D$18,'DAZZLE-日报'!$I:$I) -> 649679.93 | E22: =SUMIF('DAZZLE-日报'!$E:$E,E$18,'DAZZLE-日报'!$I:$I) -> 971970.08 | F22: =SUMIF('DAZZLE-日报'!$E:$E,F$18,'DAZZLE-日报'!$I:$I) -> 1371054.4 | G22: =SUMIF('DAZZLE-日报'!$E:$E,G$18,'DAZZLE-日报'!$I:$I) -> 2123815.6 | H22: =SUMIF('DAZZLE-日报'!$E:$E,H$18,'DAZZLE-日报'!$I:$I) -> 2063635 | I22: =SUMIF('DAZZLE-日报'!$E:$E,I$18,'DAZZLE-日报'!$I:$I) -> 2236801.1 | J22: =SUMIF('DAZZLE-日报'!$E:$E,J$18,'DAZZLE-日报'!$I:$I) -> 1415399.3 | K22: =SUMIF('DAZZLE-日报'!$E:$E,K$18,'DAZZLE-日报'!$I:$I) -> 595333.78 | ... M22: =SUMIF('DAZZLE-日报'!$E:$E,M$18,'DAZZLE-日报'!$I:$I) -> 1656604.6 | N22: =M22/L22-1 -> 0.62964889 | Q22: 4 | S22: 4
C23: 商品卡占比 | D23: =D22/D19 -> 0.28196494 | E23: =E22/E19 -> 0.21388972 | F23: =F22/F19 -> 0.26229974 | G23: =G22/G19 -> 0.37518322 | H23: =H22/H19 -> 0.3609717 | I23: =I22/I19 -> 0.39855279 | J23: =J22/J19 -> 0.32360146 | K23: =K22/K19 -> 0.46259937 | ... M23: =M22/M19 -> 0.39455001 | N23: =M23/L23-1 -> 0.43729954 | Q23: 5 | S23: 5
C24: 投放消耗金额 | D24: =SUMIF('DAZZLE-日报'!$E:$E,D$18,'DAZZLE-日报'!$K:$K) -> 8995.83 | E24: =SUMIF('DAZZLE-日报'!$E:$E,E$18,'DAZZLE-日报'!$K:$K) -> 16811.44 | F24: =SUMIF('DAZZLE-日报'!$E:$E,F$18,'DAZZLE-日报'!$K:$K) -> 16632.25 | G24: =SUMIF('DAZZLE-日报'!$E:$E,G$18,'DAZZLE-日报'!$K:$K) -> 14811.17 | H24: =SUMIF('DAZZLE-日报'!$E:$E,H$18,'DAZZLE-日报'!$K:$K) -> 17959.67 | I24: =SUMIF('DAZZLE-日报'!$E:$E,I$18,'DAZZLE-日报'!$K:$K) -> 15945.6 | J24: =SUMIF('DAZZLE-日报'!$E:$E,J$18,'DAZZLE-日报'!$K:$K) -> 13574.59 | K24: =SUMIF('DAZZLE-日报'!$E:$E,K$18,'DAZZLE-日报'!$K:$K) -> 3247.74 | ... M24: =SUMIF('DAZZLE-日报'!$E:$E,M$18,'DAZZLE-日报'!$K:$K) -> 10588.05 | N24: =M24/L24-1 -> -0.11903973 | Q24: 6 | S24: 6
C25: 投放费比 | D25: =D24/D20 -> -0.70759205 | E25: =E24/E20 -> 0.020139549 | F25: =F24/F20 -> 0.016573083 | G25: =G24/G20 -> 0.032002647 | H25: =H24/H20 -> 0.020179735 | I25: =I24/I20 -> 0.020708197 | J25: =J24/J20 -> 0.022028133 | K25: =K24/K20 -> 0.0046044542 | ... M25: =M24/M20 -> 0.019646202 | N25: =M25/L25-1 -> -0.8104139 | Q25: 7 | S25: 7
B26: 目标 | C26: GMV | D26: 2400000 | E26: 4200000 | F26: 4200000 | G26: 4200000 | H26: 4200000 | I26: 3000000 | J26: 3000000 | K26: 2000000 | L26: 3000000 | M26: 4000000 | N26: =M26/L26-1 -> 0.33333333 | Q26: 8 | S26: 8
C27: NET | D27: =D26*(1-84%) -> 384000 | E27: =E26*(1-84%) -> 672000 | F27: =F26*(1-84%) -> 672000 | G27: =G26*(1-84%) -> 672000 | H27: =H26*(1-84%) -> 672000 | I27: =I26*(1-85%) -> 450000 | J27: =J26*(1-85%) -> 450000 | K27: =K26*(1-85%) -> 300000 | L27: =L26*(1-85%) -> 450000 | M27: =M26*(1-85%) -> 600000 | N27: =M27/L27-1 -> 0.33333333 | Q27: 9 | S27: 9
C28: 退货率 | D28: =1-D27/D26 -> 0.84 | E28: =1-E27/E26 -> 0.84 | F28: =1-F27/F26 -> 0.84 | G28: =1-G27/G26 -> 0.84 | H28: =1-H27/H26 -> 0.84 | I28: =1-I27/I26 -> 0.85 | J28: =1-J27/J26 -> 0.85 | K28: =1-K27/K26 -> 0.85 | ... M28: =1-M27/M26 -> 0.85 | N28: =M28/L28-1 -> 0 | Q28: 10 | S28: 10
C29: 投放费比 | D29: 0.03 | E29: 0.03 | F29: 0.03 | G29: 0.03 | H29: 0.03 | I29: 0.03 | J29: 0.03 | K29: 0.03 | L29: 0.03 | M29: 0.03 | N29: =M29/L29-1 -> 0 | Q29: 11 | S29: 11
B30: 目标达成率 | C30: GMV | D30: =D19/D26 -> 0.96004833 | E30: =E19/E26 -> 1.0819662 | F30: =F19/F26 -> 1.2445362 | G30: =G19/G26 -> 1.3477959 | H30: =H19/H26 -> 1.3611639 | I30: =I19/I26 -> 1.8707695 | J30: =J19/J26 -> 1.4579655 | K30: =K19/K26 -> 0.64346583 | ... M30: =M19/M26 -> 1.0496797 | N30: =M30/L30-1 -> -0.14962982 | Q30: 12 | S30: 12
C31: NET | D31: =D20/D27 -> -0.033107552 | E31: =E20/E27 -> 1.2421839 | F31: =F20/F27 -> 1.4934078 | G31: =G20/G27 -> 0.68870652 | H31: =H20/H27 -> 1.3243831 | I31: =I20/I27 -> 1.7111421 | J31: =J20/J27 -> 1.3694195 | K31: =K20/K27 -> 2.3511582 | ... M31: =M20/M27 -> 0.89822705 | N31: =M31/L31-1 -> 2.4850666 | Q31: 13 | S31: 13
C32: 退货率 | D32: =D21/D28 -> 1.1970448 | E32: =E21/E28 -> 0.97179425 | F32: =F21/F28 -> 0.96191021 | G32: =G21/G28 -> 1.0931453 | H32: =H21/H28 -> 1.005147 | I32: =I21/I28 -> 1.0150577 | J32: =J21/J28 -> 1.0107175 | K32: =K21/K28 -> 0.53166516 | ... M32: =M21/M28 -> 1.025462 | N32: =M32/L32-1 -> -0.10017506 | Q32: 14 | S32: 14
C33: 投放费比 | D33: =D25/D29 -> -23.586402 | E33: =E25/E29 -> 0.67131829 | F33: =F25/F29 -> 0.5524361 | G33: =G25/G29 -> 1.0667549 | H33: =H25/H29 -> 0.67265784 | I33: =I25/I29 -> 0.69027322 | J33: =J25/J29 -> 0.73427111 | K33: =K25/K29 -> 0.15348181 | ... M33: =M25/M29 -> 0.6548734 | N33: =M33/L33-1 -> -0.8104139 | Q33: 15 | S33: 15
A34: 品牌 | D34: W1 | E34: W2 | F34: W3 | G34: W4 | H34: W5 | I34: W6 | J34: W7 | K34: W8 | L34: W9 | M34: W10 | N34: 周环比 | O34: 达成/未达成原因 | P34: 后期措施 | Q34: W10重点工作&成果 | S34: W11重点工作安排
A35: DAZZLE 视频号 | B35: 实际 | C35: GMV | D35: =SUMIF('DAZZLE（视频号）-日报'!$E:$E,D$34,'DAZZLE（视频号）-日报'!$F:$F) -> 168425 | E35: =SUMIF('DAZZLE（视频号）-日报'!$E:$E,E$34,'DAZZLE（视频号）-日报'!$F:$F) -> 451947 | F35: =SUMIF('DAZZLE（视频号）-日报'!$E:$E,F$34,'DAZZLE（视频号）-日报'!$F:$F) -> 451358 | G35: =SUMIF('DAZZLE（视频号）-日报'!$E:$E,G$34,'DAZZLE（视频号）-日报'!$F:$F) -> 362779 | H35: =SUMIF('DAZZLE（视频号）-日报'!$E:$E,H$34,'DAZZLE（视频号）-日报'!$F:$F) -> 328764 | I35: =SUMIF('DAZZLE（视频号）-日报'!$E:$E,I$34,'DAZZLE（视频号）-日报'!$F:$F) -> 297402 | J35: =SUMIF('DAZZLE（视频号）-日报'!$E:$E,J$34,'DAZZLE（视频号）-日报'!$F:$F) -> 378348 | K35: =SUMIF('DAZZLE（视频号）-日报'!$E:$E,K$34,'DAZZLE（视频号）-日报'!$F:$F) -> 195708 | ... M35: =SUMIF('DAZZLE（视频号）-日报'!$E:$E,M$34,'DAZZLE（视频号）-日报'!$F:$F) -> 430167 | N35: =M35/L35-1 -> 0.20333839 | Q35: 1 | S35: 1
C36: NET | D36: =SUMIF('DAZZLE（视频号）-日报'!$E:$E,D$34,'DAZZLE（视频号）-日报'!$G:$G) -> 7352.03 | E36: =SUMIF('DAZZLE（视频号）-日报'!$E:$E,E$34,'DAZZLE（视频号）-日报'!$G:$G) -> 125929 | F36: =SUMIF('DAZZLE（视频号）-日报'!$E:$E,F$34,'DAZZLE（视频号）-日报'!$G:$G) -> 53154 | G36: =SUMIF('DAZZLE（视频号）-日报'!$E:$E,G$34,'DAZZLE（视频号）-日报'!$G:$G) -> 21738.25 | H36: =SUMIF('DAZZLE（视频号）-日报'!$E:$E,H$34,'DAZZLE（视频号）-日报'!$G:$G) -> 58085.32 | I36: =SUMIF('DAZZLE（视频号）-日报'!$E:$E,I$34,'DAZZLE（视频号）-日报'!$G:$G) -> 37837.39 | J36: =SUMIF('DAZZLE（视频号）-日报'!$E:$E,J$34,'DAZZLE（视频号）-日报'!$G:$G) -> 107610.75 | K36: =SUMIF('DAZZLE（视频号）-日报'!$E:$E,K$34,'DAZZLE（视频号）-日报'!$G:$G) -> 130656 | ... M36: =SUMIF('DAZZLE（视频号）-日报'!$E:$E,M$34,'DAZZLE（视频号）-日报'!$G:$G) -> 118456 | N36: =M36/L36-1 -> 1.9790232 | Q36: 2 | S36: 2
C37: 退货率 | D37: =1-D36/D35 -> 0.95634834 | E37: =1-E36/E35 -> 0.72136335 | F37: =1-F36/F35 -> 0.88223539 | G37: =1-G36/G35 -> 0.94007853 | H37: =1-H36/H35 -> 0.82332214 | I37: =1-I36/I35 -> 0.87277359 | J37: =1-J36/J35 -> 0.71557733 | K37: =1-K36/K35 -> 0.33239316 | ... M37: =1-M36/M35 -> 0.72462788 | N37: =M37/L37-1 -> -0.18468179 | Q37: 3 | S37: 3
B38: 目标 | C38: GMV | D38: 800000 | E38: 1400000 | F38: 1400000 | G38: 1400000 | H38: 1400000 | I38: 650000 | J38: 650000 | K38: 650000 | L38: 650000 | M38: 650000 | N38: =M38/L38-1 -> 0 | Q38: 8 | S38: 8
C39: NET | D39: =D38*0.2 -> 160000 | E39: =E38*0.2 -> 280000 | F39: =F38*0.2 -> 280000 | G39: =G38*0.23 -> 322000 | H39: =H38*0.23 -> 322000 | I39: =I38*0.22 -> 143000 | J39: =J38*0.22 -> 143000 | K39: =K38*0.22 -> 143000 | L39: =L38*0.22 -> 143000 | M39: =M38*0.22 -> 143000 | N39: =M39/L39-1 -> 0 | Q39: 9 | S39: 9
C40: 退货率 | D40: =1-D39/D38 -> 0.8 | E40: =1-E39/E38 -> 0.8 | F40: =1-F39/F38 -> 0.8 | G40: =1-G39/G38 -> 0.77 | H40: =1-H39/H38 -> 0.77 | I40: =1-I39/I38 -> 0.78 | J40: =1-J39/J38 -> 0.78 | K40: =1-K39/K38 -> 0.78 | ... M40: =1-M39/M38 -> 0.78 | N40: =M40/L40-1 -> 0 | Q40: 10 | S40: 10
...

Sheet 2026年-行业竞品跟踪
A1: 行业 | B1: 子类 | C1: 1.1-1.4 | D1: 1.5-1.11 | E1: 1.12-1.18 | F1: 1.19-1.25 | G1: 1.26-2.1 | H1: 2.2-2.8 | I1: 2.9-2.15 | J1: 2.16-2.22 | K1: 2.23-3.1 | L1: 3.2-3.8 | M1: 周环比 | N1: 周关键变化
C2: W1 | D2: W2 | E2: W3 | F2: W4 | G2: W5 | H2: W6 | I2: W7 | J2: W8 | K2: W9 | L2: W10
A3: 女装 | B3: 总计 | C3: =SUMIF('女装-品类销售明细'!$C:$C,C$2,'女装-品类销售明细'!$I:$I) -> 1.5774031e+10 | D3: =SUMIF('女装-品类销售明细'!$C:$C,D$2,'女装-品类销售明细'!$I:$I) -> 2.9456159e+10 | E3: =SUMIF('女装-品类销售明细'!$C:$C,E$2,'女装-品类销售明细'!$I:$I) -> 2.8343911e+10 | F3: =SUMIF('女装-品类销售明细'!$C:$C,F$2,'女装-品类销售明细'!$I:$I) -> 2.6033953e+10 | G3: =SUMIF('女装-品类销售明细'!$C:$C,G$2,'女装-品类销售明细'!$I:$I) -> 2.3243439e+10 | H3: =SUMIF('女装-品类销售明细'!$C:$C,H$2,'女装-品类销售明细'!$I:$I) -> 2.0999516e+10 | I3: =SUMIF('女装-品类销售明细'!$C:$C,I$2,'女装-品类销售明细'!$I:$I) -> 1.0780144e+10 | J3: =SUMIF('女装-品类销售明细'!$C:$C,J$2,'女装-品类销售明细'!$I:$I) -> 7.1820793e+09 | ... L3: =SUMIF('女装-品类销售明细'!$C:$C,L$2,'女装-品类销售明细'!$I:$I) -> 1.1240004e+10 | M3: =L3/K3-1 -> -0.14291742 | N3: 女装3月裤子、短外套、制服为行业TOP品类，TOP商品为唐发发、lucas等达人品牌
B4: 羽绒服 | C4: =SUMIFS('女装-品类销售明细'!$I:$I,'女装-品类销售明细'!$C:$C,C$2,'女装-品类销售明细'!$G:$G,$B4) -> 3.6909943e+09 | D4: =SUMIFS('女装-品类销售明细'!$I:$I,'女装-品类销售明细'!$C:$C,D$2,'女装-品类销售明细'!$G:$G,$B4) -> 6.5543407e+09 | E4: =SUMIFS('女装-品类销售明细'!$I:$I,'女装-品类销售明细'!$C:$C,E$2,'女装-品类销售明细'!$G:$G,$B4) -> 5.7873272e+09 | F4: =SUMIFS('女装-品类销售明细'!$I:$I,'女装-品类销售明细'!$C:$C,F$2,'女装-品类销售明细'!$G:$G,$B4) -> 6.01545e+09 | G4: =SUMIFS('女装-品类销售明细'!$I:$I,'女装-品类销售明细'!$C:$C,G$2,'女装-品类销售明细'!$G:$G,$B4) -> 4.5474167e+09 | H4: =SUMIFS('女装-品类销售明细'!$I:$I,'女装-品类销售明细'!$C:$C,H$2,'女装-品类销售明细'!$G:$G,$B4) -> 3.5706335e+09 | I4: =SUMIFS('女装-品类销售明细'!$I:$I,'女装-品类销售明细'!$C:$C,I$2,'女装-品类销售明细'!$G:$G,$B4) -> 1.5042211e+09 | J4: =SUMIFS('女装-品类销售明细'!$I:$I,'女装-品类销售明细'!$C:$C,J$2,'女装-品类销售明细'!$G:$G,$B4) -> 3.6859033e+08 | ... L4: =SUMIFS('女装-品类销售明细'!$I:$I,'女装-品类销售明细'!$C:$C,L$2,'女装-品类销售明细'!$G:$G,$B4) -> 4.643779e+08 | M4: =L4/K4-1 -> -0.19205433
B5: 裤子 | C5: =SUMIFS('女装-品类销售明细'!$I:$I,'女装-品类销售明细'!$C:$C,C$2,'女装-品类销售明细'!$G:$G,$B5) -> 1.992412e+09 | D5: =SUMIFS('女装-品类销售明细'!$I:$I,'女装-品类销售明细'!$C:$C,D$2,'女装-品类销售明细'!$G:$G,$B5) -> 3.6534308e+09 | E5: =SUMIFS('女装-品类销售明细'!$I:$I,'女装-品类销售明细'!$C:$C,E$2,'女装-品类销售明细'!$G:$G,$B5) -> 3.3824702e+09 | F5: =SUMIFS('女装-品类销售明细'!$I:$I,'女装-品类销售明细'!$C:$C,F$2,'女装-品类销售明细'!$G:$G,$B5) -> 3.0231186e+09 | G5: =SUMIFS('女装-品类销售明细'!$I:$I,'女装-品类销售明细'!$C:$C,G$2,'女装-品类销售明细'!$G:$G,$B5) -> 2.7553911e+09 | H5: =SUMIFS('女装-品类销售明细'!$I:$I,'女装-品类销售明细'!$C:$C,H$2,'女装-品类销售明细'!$G:$G,$B5) -> 2.5004961e+09 | I5: =SUMIFS('女装-品类销售明细'!$I:$I,'女装-品类销售明细'!$C:$C,I$2,'女装-品类销售明细'!$G:$G,$B5) -> 1.1770306e+09 | J5: =SUMIFS('女装-品类销售明细'!$I:$I,'女装-品类销售明细'!$C:$C,J$2,'女装-品类销售明细'!$G:$G,$B5) -> 9.7269023e+08 | ... L5: =SUMIFS('女装-品类销售明细'!$I:$I,'女装-品类销售明细'!$C:$C,L$2,'女装-品类销售明细'!$G:$G,$B5) -> 1.8875436e+09 | M5: =L5/K5-1 -> -0.080373972
B6: 皮草 | C6: =SUMIFS('女装-品类销售明细'!$I:$I,'女装-品类销售明细'!$C:$C,C$2,'女装-品类销售明细'!$G:$G,$B6) -> 1.7638643e+09 | D6: =SUMIFS('女装-品类销售明细'!$I:$I,'女装-品类销售明细'!$C:$C,D$2,'女装-品类销售明细'!$G:$G,$B6) -> 3.494858e+09 | E6: =SUMIFS('女装-品类销售明细'!$I:$I,'女装-品类销售明细'!$C:$C,E$2,'女装-品类销售明细'!$G:$G,$B6) -> 3.3075553e+09 | F6: =SUMIFS('女装-品类销售明细'!$I:$I,'女装-品类销售明细'!$C:$C,F$2,'女装-品类销售明细'!$G:$G,$B6) -> 3.0968458e+09 | G6: =SUMIFS('女装-品类销售明细'!$I:$I,'女装-品类销售明细'!$C:$C,G$2,'女装-品类销售明细'!$G:$G,$B6) -> 2.5923623e+09 | H6: =SUMIFS('女装-品类销售明细'!$I:$I,'女装-品类销售明细'!$C:$C,H$2,'女装-品类销售明细'!$G:$G,$B6) -> 1.9682827e+09 | I6: =SUMIFS('女装-品类销售明细'!$I:$I,'女装-品类销售明细'!$C:$C,I$2,'女装-品类销售明细'!$G:$G,$B6) -> 1.04112e+09 | J6: =SUMIFS('女装-品类销售明细'!$I:$I,'女装-品类销售明细'!$C:$C,J$2,'女装-品类销售明细'!$G:$G,$B6) -> 3.7401703e+08 | ... L6: =SUMIFS('女装-品类销售明细'!$I:$I,'女装-品类销售明细'!$C:$C,L$2,'女装-品类销售明细'!$G:$G,$B6) -> 2.894328e+08 | M6: =L6/K6-1 -> -0.25324019
B7: 毛呢外套 | C7: =SUMIFS('女装-品类销售明细'!$I:$I,'女装-品类销售明细'!$C:$C,C$2,'女装-品类销售明细'!$G:$G,$B7) -> 1.1294749e+09 | D7: =SUMIFS('女装-品类销售明细'!$I:$I,'女装-品类销售明细'!$C:$C,D$2,'女装-品类销售明细'!$G:$G,$B7) -> 2.2988587e+09 | E7: =SUMIFS('女装-品类销售明细'!$I:$I,'女装-品类销售明细'!$C:$C,E$2,'女装-品类销售明细'!$G:$G,$B7) -> 2.3975557e+09 | F7: =SUMIFS('女装-品类销售明细'!$I:$I,'女装-品类销售明细'!$C:$C,F$2,'女装-品类销售明细'!$G:$G,$B7) -> 2.1733749e+09 | G7: =SUMIFS('女装-品类销售明细'!$I:$I,'女装-品类销售明细'!$C:$C,G$2,'女装-品类销售明细'!$G:$G,$B7) -> 2.1960572e+09 | H7: =SUMIFS('女装-品类销售明细'!$I:$I,'女装-品类销售明细'!$C:$C,H$2,'女装-品类销售明细'!$G:$G,$B7) -> 2.2605817e+09 | I7: =SUMIFS('女装-品类销售明细'!$I:$I,'女装-品类销售明细'!$C:$C,I$2,'女装-品类销售明细'!$G:$G,$B7) -> 1.2334271e+09 | J7: =SUMIFS('女装-品类销售明细'!$I:$I,'女装-品类销售明细'!$C:$C,J$2,'女装-品类销售明细'!$G:$G,$B7) -> 5.0428934e+08 | ... L7: =SUMIFS('女装-品类销售明细'!$I:$I,'女装-品类销售明细'!$C:$C,L$2,'女装-品类销售明细'!$G:$G,$B7) -> 3.832651e+08 | M7: =L7/K7-1 -> -0.34207614
B8: 短外套 | C8: =SUMIFS('女装-品类销售明细'!$I:$I,'女装-品类销售明细'!$C:$C,C$2,'女装-品类销售明细'!$G:$G,$B8) -> 1.2223895e+09 | D8: =SUMIFS('女装-品类销售明细'!$I:$I,'女装-品类销售明细'!$C:$C,D$2,'女装-品类销售明细'!$G:$G,$B8) -> 2.3389406e+09 | E8: =SUMIFS('女装-品类销售明细'!$I:$I,'女装-品类销售明细'!$C:$C,E$2,'女装-品类销售明细'!$G:$G,$B8) -> 2.2592979e+09 | F8: =SUMIFS('女装-品类销售明细'!$I:$I,'女装-品类销售明细'!$C:$C,F$2,'女装-品类销售明细'!$G:$G,$B8) -> 1.9907418e+09 | G8: =SUMIFS('女装-品类销售明细'!$I:$I,'女装-品类销售明细'!$C:$C,G$2,'女装-品类销售明细'!$G:$G,$B8) -> 1.8154165e+09 | H8: =SUMIFS('女装-品类销售明细'!$I:$I,'女装-品类销售明细'!$C:$C,H$2,'女装-品类销售明细'!$G:$G,$B8) -> 1.7019438e+09 | I8: =SUMIFS('女装-品类销售明细'!$I:$I,'女装-品类销售明细'!$C:$C,I$2,'女装-品类销售明细'!$G:$G,$B8) -> 8.5299712e+08 | J8: =SUMIFS('女装-品类销售明细'!$I:$I,'女装-品类销售明细'!$C:$C,J$2,'女装-品类销售明细'!$G:$G,$B8) -> 6.0443885e+08 | ... L8: =SUMIFS('女装-品类销售明细'!$I:$I,'女装-品类销售明细'!$C:$C,L$2,'女装-品类销售明细'!$G:$G,$B8) -> 8.7856331e+08 | M8: =L8/K8-1 -> -0.13604478
B9: 毛针织衫 | C9: =SUMIFS('女装-品类销售明细'!$I:$I,'女装-品类销售明细'!$C:$C,C$2,'女装-品类销售明细'!$G:$G,$B9) -> 8.3580089e+08 | D9: =SUMIFS('女装-品类销售明细'!$I:$I,'女装-品类销售明细'!$C:$C,D$2,'女装-品类销售明细'!$G:$G,$B9) -> 1.5271795e+09 | E9: =SUMIFS('女装-品类销售明细'!$I:$I,'女装-品类销售明细'!$C:$C,E$2,'女装-品类销售明细'!$G:$G,$B9) -> 1.4925484e+09 | F9: =SUMIFS('女装-品类销售明细'!$I:$I,'女装-品类销售明细'!$C:$C,F$2,'女装-品类销售明细'!$G:$G,$B9) -> 1.2552472e+09 | G9: =SUMIFS('女装-品类销售明细'!$I:$I,'女装-品类销售明细'!$C:$C,G$2,'女装-品类销售明细'!$G:$G,$B9) -> 1.2649956e+09 | H9: =SUMIFS('女装-品类销售明细'!$I:$I,'女装-品类销售明细'!$C:$C,H$2,'女装-品类销售明细'!$G:$G,$B9) -> 1.225105e+09 | I9: =SUMIFS('女装-品类销售明细'!$I:$I,'女装-品类销售明细'!$C:$C,I$2,'女装-品类销售明细'!$G:$G,$B9) -> 6.0583994e+08 | J9: =SUMIFS('女装-品类销售明细'!$I:$I,'女装-品类销售明细'!$C:$C,J$2,'女装-品类销售明细'!$G:$G,$B9) -> 3.9571464e+08 | ... L9: =SUMIFS('女装-品类销售明细'!$I:$I,'女装-品类销售明细'!$C:$C,L$2,'女装-品类销售明细'!$G:$G,$B9) -> 6.6613623e+08 | M9: =L9/K9-1 -> -0.095646499
B10: 套装/学生校服/工作制服 | C10: =SUMIFS('女装-品类销售明细'!$I:$I,'女装-品类销售明细'!$C:$C,C$2,'女装-品类销售明细'!$G:$G,$B10) -> 5.1385935e+08 | D10: =SUMIFS('女装-品类销售明细'!$I:$I,'女装-品类销售明细'!$C:$C,D$2,'女装-品类销售明细'!$G:$G,$B10) -> 1.0256684e+09 | E10: =SUMIFS('女装-品类销售明细'!$I:$I,'女装-品类销售明细'!$C:$C,E$2,'女装-品类销售明细'!$G:$G,$B10) -> 1.0583934e+09 | F10: =SUMIFS('女装-品类销售明细'!$I:$I,'女装-品类销售明细'!$C:$C,F$2,'女装-品类销售明细'!$G:$G,$B10) -> 8.7488052e+08 | G10: =SUMIFS('女装-品类销售明细'!$I:$I,'女装-品类销售明细'!$C:$C,G$2,'女装-品类销售明细'!$G:$G,$B10) -> 8.4553027e+08 | H10: =SUMIFS('女装-品类销售明细'!$I:$I,'女装-品类销售明细'!$C:$C,H$2,'女装-品类销售明细'!$G:$G,$B10) -> 8.4748374e+08 | I10: =SUMIFS('女装-品类销售明细'!$I:$I,'女装-品类销售明细'!$C:$C,I$2,'女装-品类销售明细'!$G:$G,$B10) -> 4.8431745e+08 | J10: =SUMIFS('女装-品类销售明细'!$I:$I,'女装-品类销售明细'!$C:$C,J$2,'女装-品类销售明细'!$G:$G,$B10) -> 5.4355274e+08 | ... L10: =SUMIFS('女装-品类销售明细'!$I:$I,'女装-品类销售明细'!$C:$C,L$2,'女装-品类销售明细'!$G:$G,$B10) -> 8.6200163e+08 | M10: =L10/K10-1 -> -0.11246082
B11: 棉衣/棉服 | C11: =SUMIFS('女装-品类销售明细'!$I:$I,'女装-品类销售明细'!$C:$C,C$2,'女装-品类销售明细'!$G:$G,$B11) -> 4.4754223e+08 | D11: =SUMIFS('女装-品类销售明细'!$I:$I,'女装-品类销售明细'!$C:$C,D$2,'女装-品类销售明细'!$G:$G,$B11) -> 8.2795625e+08 | E11: =SUMIFS('女装-品类销售明细'!$I:$I,'女装-品类销售明细'!$C:$C,E$2,'女装-品类销售明细'!$G:$G,$B11) -> 7.1441661e+08 | F11: =SUMIFS('女装-品类销售明细'!$I:$I,'女装-品类销售明细'!$C:$C,F$2,'女装-品类销售明细'!$G:$G,$B11) -> 6.5335219e+08 | G11: =SUMIFS('女装-品类销售明细'!$I:$I,'女装-品类销售明细'!$C:$C,G$2,'女装-品类销售明细'!$G:$G,$B11) -> 5.6781032e+08 | H11: =SUMIFS('女装-品类销售明细'!$I:$I,'女装-品类销售明细'!$C:$C,H$2,'女装-品类销售明细'!$G:$G,$B11) -> 4.7647234e+08 | I11: =SUMIFS('女装-品类销售明细'!$I:$I,'女装-品类销售明细'!$C:$C,I$2,'女装-品类销售明细'!$G:$G,$B11) -> 2.0971026e+08 | J11: =SUMIFS('女装-品类销售明细'!$I:$I,'女装-品类销售明细'!$C:$C,J$2,'女装-品类销售明细'!$G:$G,$B11) -> 76072748 | ... L11: =SUMIFS('女装-品类销售明细'!$I:$I,'女装-品类销售明细'!$C:$C,L$2,'女装-品类销售明细'!$G:$G,$B11) -> 1.0246709e+08 | M11: =L11/K11-1 -> -0.22971324
B12: 连衣裙 | C12: =SUMIFS('女装-品类销售明细'!$I:$I,'女装-品类销售明细'!$C:$C,C$2,'女装-品类销售明细'!$G:$G,$B12) -> 3.7536787e+08 | D12: =SUMIFS('女装-品类销售明细'!$I:$I,'女装-品类销售明细'!$C:$C,D$2,'女装-品类销售明细'!$G:$G,$B12) -> 7.6012306e+08 | E12: =SUMIFS('女装-品类销售明细'!$I:$I,'女装-品类销售明细'!$C:$C,E$2,'女装-品类销售明细'!$G:$G,$B12) -> 7.9439538e+08 | F12: =SUMIFS('女装-品类销售明细'!$I:$I,'女装-品类销售明细'!$C:$C,F$2,'女装-品类销售明细'!$G:$G,$B12) -> 6.7089778e+08 | G12: =SUMIFS('女装-品类销售明细'!$I:$I,'女装-品类销售明细'!$C:$C,G$2,'女装-品类销售明细'!$G:$G,$B12) -> 6.8750437e+08 | H12: =SUMIFS('女装-品类销售明细'!$I:$I,'女装-品类销售明细'!$C:$C,H$2,'女装-品类销售明细'!$G:$G,$B12) -> 7.2605512e+08 | I12: =SUMIFS('女装-品类销售明细'!$I:$I,'女装-品类销售明细'!$C:$C,I$2,'女装-品类销售明细'!$G:$G,$B12) -> 4.8429199e+08 | J12: =SUMIFS('女装-品类销售明细'!$I:$I,'女装-品类销售明细'!$C:$C,J$2,'女装-品类销售明细'!$G:$G,$B12) -> 4.8133275e+08 | ... L12: =SUMIFS('女装-品类销售明细'!$I:$I,'女装-品类销售明细'!$C:$C,L$2,'女装-品类销售明细'!$G:$G,$B12) -> 8.2742336e+08 | M12: =L12/K12-1 -> -0.094456673
B13: 汉服 | C13: =SUMIFS('女装-品类销售明细'!$I:$I,'女装-品类销售明细'!$C:$C,C$2,'女装-品类销售明细'!$G:$G,$B13) -> 3.4202961e+08 | D13: =SUMIFS('女装-品类销售明细'!$I:$I,'女装-品类销售明细'!$C:$C,D$2,'女装-品类销售明细'!$G:$G,$B13) -> 5.6991605e+08 | E13: =SUMIFS('女装-品类销售明细'!$I:$I,'女装-品类销售明细'!$C:$C,E$2,'女装-品类销售明细'!$G:$G,$B13) -> 6.3974023e+08 | F13: =SUMIFS('女装-品类销售明细'!$I:$I,'女装-品类销售明细'!$C:$C,F$2,'女装-品类销售明细'!$G:$G,$B13) -> 5.6224573e+08 | G13: =SUMIFS('女装-品类销售明细'!$I:$I,'女装-品类销售明细'!$C:$C,G$2,'女装-品类销售明细'!$G:$G,$B13) -> 4.133411e+08 | H13: =SUMIFS('女装-品类销售明细'!$I:$I,'女装-品类销售明细'!$C:$C,H$2,'女装-品类销售明细'!$G:$G,$B13) -> 3.4257381e+08 | I13: =SUMIFS('女装-品类销售明细'!$I:$I,'女装-品类销售明细'!$C:$C,I$2,'女装-品类销售明细'!$G:$G,$B13) -> 2.2392502e+08 | J13: =SUMIFS('女装-品类销售明细'!$I:$I,'女装-品类销售明细'!$C:$C,J$2,'女装-品类销售明细'!$G:$G,$B13) -> 2.616555e+08 | ... L13: =SUMIFS('女装-品类销售明细'!$I:$I,'女装-品类销售明细'!$C:$C,L$2,'女装-品类销售明细'!$G:$G,$B13) -> 3.1731798e+08 | M13: =L13/K13-1 -> -0.48244288
B14: T恤 | C14: =SUMIFS('女装-品类销售明细'!$I:$I,'女装-品类销售明细'!$C:$C,C$2,'女装-品类销售明细'!$G:$G,$B14) -> 3.466147e+08 | D14: =SUMIFS('女装-品类销售明细'!$I:$I,'女装-品类销售明细'!$C:$C,D$2,'女装-品类销售明细'!$G:$G,$B14) -> 6.4555713e+08 | E14: =SUMIFS('女装-品类销售明细'!$I:$I,'女装-品类销售明细'!$C:$C,E$2,'女装-品类销售明细'!$G:$G,$B14) -> 6.5485147e+08 | F14: =SUMIFS('女装-品类销售明细'!$I:$I,'女装-品类销售明细'!$C:$C,F$2,'女装-品类销售明细'!$G:$G,$B14) -> 5.428292e+08 | G14: =SUMIFS('女装-品类销售明细'!$I:$I,'女装-品类销售明细'!$C:$C,G$2,'女装-品类销售明细'!$G:$G,$B14) -> 5.5292836e+08 | H14: =SUMIFS('女装-品类销售明细'!$I:$I,'女装-品类销售明细'!$C:$C,H$2,'女装-品类销售明细'!$G:$G,$B14) -> 5.6920843e+08 | I14: =SUMIFS('女装-品类销售明细'!$I:$I,'女装-品类销售明细'!$C:$C,I$2,'女装-品类销售明细'!$G:$G,$B14) -> 3.6441938e+08 | J14: =SUMIFS('女装-品类销售明细'!$I:$I,'女装-品类销售明细'!$C:$C,J$2,'女装-品类销售明细'!$G:$G,$B14) -> 3.8979497e+08 | ... L14: =SUMIFS('女装-品类销售明细'!$I:$I,'女装-品类销售明细'!$C:$C,L$2,'女装-品类销售明细'!$G:$G,$B14) -> 7.8339826e+08 | M14: =L14/K14-1 -> -0.071574667
B15: 羊毛衫 | C15: =SUMIFS('女装-品类销售明细'!$I:$I,'女装-品类销售明细'!$C:$C,C$2,'女装-品类销售明细'!$G:$G,$B15) -> 3.2711365e+08 | D15: =SUMIFS('女装-品类销售明细'!$I:$I,'女装-品类销售明细'!$C:$C,D$2,'女装-品类销售明细'!$G:$G,$B15) -> 5.6454322e+08 | E15: =SUMIFS('女装-品类销售明细'!$I:$I,'女装-品类销售明细'!$C:$C,E$2,'女装-品类销售明细'!$G:$G,$B15) -> 5.4039244e+08 | F15: =SUMIFS('女装-品类销售明细'!$I:$I,'女装-品类销售明细'!$C:$C,F$2,'女装-品类销售明细'!$G:$G,$B15) -> 4.7150448e+08 | G15: =SUMIFS('女装-品类销售明细'!$I:$I,'女装-品类销售明细'!$C:$C,G$2,'女装-品类销售明细'!$G:$G,$B15) -> 4.3148872e+08 | H15: =SUMIFS('女装-品类销售明细'!$I:$I,'女装-品类销售明细'!$C:$C,H$2,'女装-品类销售明细'!$G:$G,$B15) -> 3.6759399e+08 | I15: =SUMIFS('女装-品类销售明细'!$I:$I,'女装-品类销售明细'!$C:$C,I$2,'女装-品类销售明细'!$G:$G,$B15) -> 1.7074431e+08 | J15: =SUMIFS('女装-品类销售明细'!$I:$I,'女装-品类销售明细'!$C:$C,J$2,'女装-品类销售明细'!$G:$G,$B15) -> 74077572 | ... L15: =SUMIFS('女装-品类销售明细'!$I:$I,'女装-品类销售明细'!$C:$C,L$2,'女装-品类销售明细'!$G:$G,$B15) -> 1.1969829e+08 | M15: =L15/K15-1 -> -0.19143362
... B23: 衬衫 | C23: =SUMIFS('女装-品类销售明细'!$I:$I,'女装-品类销售明细'!$C:$C,C$2,'女装-品类销售明细'!$G:$G,$B23) -> 1.7728861e+08 | D23: =SUMIFS('女装-品类销售明细'!$I:$I,'女装-品类销售明细'!$C:$C,D$2,'女装-品类销售明细'!$G:$G,$B23) -> 3.6254178e+08 | E23: =SUMIFS('女装-品类销售明细'!$I:$I,'女装-品类销售明细'!$C:$C,E$2,'女装-品类销售明细'!$G:$G,$B23) -> 4.1456181e+08 | F23: =SUMIFS('女装-品类销售明细'!$I:$I,'女装-品类销售明细'!$C:$C,F$2,'女装-品类销售明细'!$G:$G,$B23) -> 3.4254805e+08 | G23: =SUMIFS('女装-品类销售明细'!$I:$I,'女装-品类销售明细'!$C:$C,G$2,'女装-品类销售明细'!$G:$G,$B23) -> 3.5216652e+08 | H23: =SUMIFS('女装-品类销售明细'!$I:$I,'女装-品类销售明细'!$C:$C,H$2,'女装-品类销售明细'!$G:$G,$B23) -> 3.8471656e+08 | I23: =SUMIFS('女装-品类销售明细'!$I:$I,'女装-品类销售明细'!$C:$C,I$2,'女装-品类销售明细'!$G:$G,$B23) -> 2.5669686e+08 | J23: =SUMIFS('女装-品类销售明细'!$I:$I,'女装-品类销售明细'!$C:$C,J$2,'女装-品类销售明细'!$G:$G,$B23) -> 3.191767e+08 | ... L23: =SUMIFS('女装-品类销售明细'!$I:$I,'女装-品类销售明细'!$C:$C,L$2,'女装-品类销售明细'!$G:$G,$B23) -> 5.7799313e+08 | M23: =L23/K23-1 -> -0.12681129
A24: 男装 | B24: 总计 | C24: =SUMIF('男装-品类销售明细'!$C:$C,C$2,'男装-品类销售明细'!$I:$I) -> 3.6356234e+09 | D24: =SUMIF('男装-品类销售明细'!$C:$C,D$2,'男装-品类销售明细'!$I:$I) -> 6.4609903e+09 | E24: =SUMIF('男装-品类销售明细'!$C:$C,E$2,'男装-品类销售明细'!$I:$I) -> 5.8247083e+09 | F24: =SUMIF('男装-品类销售明细'!$C:$C,F$2,'男装-品类销售明细'!$I:$I) -> 6.2037542e+09 | G24: =SUMIF('男装-品类销售明细'!$C:$C,G$2,'男装-品类销售明细'!$I:$I) -> 5.715387e+09 | H24: =SUMIF('男装-品类销售明细'!$C:$C,H$2,'男装-品类销售明细'!$I:$I) -> 5.8179538e+09 | I24: =SUMIF('男装-品类销售明细'!$C:$C,I$2,'男装-品类销售明细'!$I:$I) -> 2.555649e+09 | J24: =SUMIF('男装-品类销售明细'!$C:$C,J$2,'男装-品类销售明细'!$I:$I) -> 1.0539623e+09 | ... L24: =SUMIF('男装-品类销售明细'!$C:$C,L$2,'男装-品类销售明细'!$I:$I) -> 1.8194574e+09 | M24: =L24/K24-1 -> -0.059232368 | N24: 3月截止7日夹克、T恤、休闲裤为行业TOP品类，其中夹克主要为德尔惠、西域骆驼品牌的冲锋衣、T恤为白小T、霞湖世家的T
B25: 羽绒服 | C25: =SUMIFS('男装-品类销售明细'!$I:$I,'男装-品类销售明细'!$C:$C,C$2,'男装-品类销售明细'!$G:$G,$B25) -> 1.010145e+09 | D25: =SUMIFS('男装-品类销售明细'!$I:$I,'男装-品类销售明细'!$C:$C,D$2,'男装-品类销售明细'!$G:$G,$B25) -> 1.8217393e+09 | E25: =SUMIFS('男装-品类销售明细'!$I:$I,'男装-品类销售明细'!$C:$C,E$2,'男装-品类销售明细'!$G:$G,$B25) -> 1.6525094e+09 | F25: =SUMIFS('男装-品类销售明细'!$I:$I,'男装-品类销售明细'!$C:$C,F$2,'男装-品类销售明细'!$G:$G,$B25) -> 1.8155163e+09 | G25: =SUMIFS('男装-品类销售明细'!$I:$I,'男装-品类销售明细'!$C:$C,G$2,'男装-品类销售明细'!$G:$G,$B25) -> 1.5261421e+09 | H25: =SUMIFS('男装-品类销售明细'!$I:$I,'男装-品类销售明细'!$C:$C,H$2,'男装-品类销售明细'!$G:$G,$B25) -> 1.3191202e+09 | I25: =SUMIFS('男装-品类销售明细'!$I:$I,'男装-品类销售明细'!$C:$C,I$2,'男装-品类销售明细'!$G:$G,$B25) -> 4.8248177e+08 | J25: =SUMIFS('男装-品类销售明细'!$I:$I,'男装-品类销售明细'!$C:$C,J$2,'男装-品类销售明细'!$G:$G,$B25) -> 48873978 | ... L25: =SUMIFS('男装-品类销售明细'!$I:$I,'男装-品类销售明细'!$C:$C,L$2,'男装-品类销售明细'!$G:$G,$B25) -> 69957568 | M25: =L25/K25-1 -> -0.1313529
B26: 休闲裤 | C26: =SUMIFS('男装-品类销售明细'!$I:$I,'男装-品类销售明细'!$C:$C,C$2,'男装-品类销售明细'!$G:$G,$B26) -> 4.4415925e+08 | D26: =SUMIFS('男装-品类销售明细'!$I:$I,'男装-品类销售明细'!$C:$C,D$2,'男装-品类销售明细'!$G:$G,$B26) -> 7.5578979e+08 | E26: =SUMIFS('男装-品类销售明细'!$I:$I,'男装-品类销售明细'!$C:$C,E$2,'男装-品类销售明细'!$G:$G,$B26) -> 6.4752562e+08 | F26: =SUMIFS('男装-品类销售明细'!$I:$I,'男装-品类销售明细'!$C:$C,F$2,'男装-品类销售明细'!$G:$G,$B26) -> 7.2102652e+08 | G26: =SUMIFS('男装-品类销售明细'!$I:$I,'男装-品类销售明细'!$C:$C,G$2,'男装-品类销售明细'!$G:$G,$B26) -> 6.5124034e+08 | H26: =SUMIFS('男装-品类销售明细'!$I:$I,'男装-品类销售明细'!$C:$C,H$2,'男装-品类销售明细'!$G:$G,$B26) -> 6.719057e+08 | I26: =SUMIFS('男装-品类销售明细'!$I:$I,'男装-品类销售明细'!$C:$C,I$2,'男装-品类销售明细'!$G:$G,$B26) -> 2.7137358e+08 | J26: =SUMIFS('男装-品类销售明细'!$I:$I,'男装-品类销售明细'!$C:$C,J$2,'男装-品类销售明细'!$G:$G,$B26) -> 1.1341844e+08 | ... L26: =SUMIFS('男装-品类销售明细'!$I:$I,'男装-品类销售明细'!$C:$C,L$2,'男装-品类销售明细'!$G:$G,$B26) -> 2.2907644e+08 | M26: =L26/K26-1 -> -0.013908611
B27: 夹克 | C27: =SUMIFS('男装-品类销售明细'!$I:$I,'男装-品类销售明细'!$C:$C,C$2,'男装-品类销售明细'!$G:$G,$B27) -> 3.122099e+08 | D27: =SUMIFS('男装-品类销售明细'!$I:$I,'男装-品类销售明细'!$C:$C,D$2,'男装-品类销售明细'!$G:$G,$B27) -> 5.8952566e+08 | E27: =SUMIFS('男装-品类销售明细'!$I:$I,'男装-品类销售明细'!$C:$C,E$2,'男装-品类销售明细'!$G:$G,$B27) -> 5.5882267e+08 | F27: =SUMIFS('男装-品类销售明细'!$I:$I,'男装-品类销售明细'!$C:$C,F$2,'男装-品类销售明细'!$G:$G,$B27) -> 5.6333746e+08 | G27: =SUMIFS('男装-品类销售明细'!$I:$I,'男装-品类销售明细'!$C:$C,G$2,'男装-品类销售明细'!$G:$G,$B27) -> 5.7156317e+08 | H27: =SUMIFS('男装-品类销售明细'!$I:$I,'男装-品类销售明细'!$C:$C,H$2,'男装-品类销售明细'!$G:$G,$B27) -> 6.7160558e+08 | I27: =SUMIFS('男装-品类销售明细'!$I:$I,'男装-品类销售明细'!$C:$C,I$2,'男装-品类销售明细'!$G:$G,$B27) -> 3.6628613e+08 | J27: =SUMIFS('男装-品类销售明细'!$I:$I,'男装-品类销售明细'!$C:$C,J$2,'男装-品类销售明细'!$G:$G,$B27) -> 2.0758133e+08 | ... L27: =SUMIFS('男装-品类销售明细'!$I:$I,'男装-品类销售明细'!$C:$C,L$2,'男装-品类销售明细'!$G:$G,$B27) -> 4.0193211e+08 | M27: =L27/K27-1 -> -0.0083852805
B28: 牛仔裤 | C28: =SUMIFS('男装-品类销售明细'!$I:$I,'男装-品类销售明细'!$C:$C,C$2,'男装-品类销售明细'!$G:$G,$B28) -> 2.7165865e+08 | D28: =SUMIFS('男装-品类销售明细'!$I:$I,'男装-品类销售明细'!$C:$C,D$2,'男装-品类销售明细'!$G:$G,$B28) -> 4.7784218e+08 | E28: =SUMIFS('男装-品类销售明细'!$I:$I,'男装-品类销售明细'!$C:$C,E$2,'男装-品类销售明细'!$G:$G,$B28) -> 4.5338723e+08 | F28: =SUMIFS('男装-品类销售明细'!$I:$I,'男装-品类销售明细'!$C:$C,F$2,'男装-品类销售明细'!$G:$G,$B28) -> 4.7765462e+08 | G28: =SUMIFS('男装-品类销售明细'!$I:$I,'男装-品类销售明细'!$C:$C,G$2,'男装-品类销售明细'!$G:$G,$B28) -> 5.0487838e+08 | H28: =SUMIFS('男装-品类销售明细'!$I:$I,'男装-品类销售明细'!$C:$C,H$2,'男装-品类销售明细'!$G:$G,$B28) -> 5.5438552e+08 | I28: =SUMIFS('男装-品类销售明细'!$I:$I,'男装-品类销售明细'!$C:$C,I$2,'男装-品类销售明细'!$G:$G,$B28) -> 2.3710386e+08 | J28: =SUMIFS('男装-品类销售明细'!$I:$I,'男装-品类销售明细'!$C:$C,J$2,'男装-品类销售明细'!$G:$G,$B28) -> 1.0658688e+08 | ... L28: =SUMIFS('男装-品类销售明细'!$I:$I,'男装-品类销售明细'!$C:$C,L$2,'男装-品类销售明细'!$G:$G,$B28) -> 1.7649356e+08 | M28: =L28/K28-1 -> -0.060261027
B29: 棉衣 | C29: =SUMIFS('男装-品类销售明细'!$I:$I,'男装-品类销售明细'!$C:$C,C$2,'男装-品类销售明细'!$G:$G,$B29) -> 2.4380564e+08 | D29: =SUMIFS('男装-品类销售明细'!$I:$I,'男装-品类销售明细'!$C:$C,D$2,'男装-品类销售明细'!$G:$G,$B29) -> 4.447307e+08 | E29: =SUMIFS('男装-品类销售明细'!$I:$I,'男装-品类销售明细'!$C:$C,E$2,'男装-品类销售明细'!$G:$G,$B29) -> 3.4372697e+08 | F29: =SUMIFS('男装-品类销售明细'!$I:$I,'男装-品类销售明细'!$C:$C,F$2,'男装-品类销售明细'!$G:$G,$B29) -> 3.8419563e+08 | G29: =SUMIFS('男装-品类销售明细'!$I:$I,'男装-品类销售明细'!$C:$C,G$2,'男装-品类销售明细'!$G:$G,$B29) -> 3.3544012e+08 | H29: =SUMIFS('男装-品类销售明细'!$I:$I,'男装-品类销售明细'!$C:$C,H$2,'男装-品类销售明细'!$G:$G,$B29) -> 3.2143638e+08 | I29: =SUMIFS('男装-品类销售明细'!$I:$I,'男装-品类销售明细'!$C:$C,I$2,'男装-品类销售明细'!$G:$G,$B29) -> 1.2432645e+08 | J29: =SUMIFS('男装-品类销售明细'!$I:$I,'男装-品类销售明细'!$C:$C,J$2,'男装-品类销售明细'!$G:$G,$B29) -> 18969406 | ... L29: =SUMIFS('男装-品类销售明细'!$I:$I,'男装-品类销售明细'!$C:$C,L$2,'男装-品类销售明细'!$G:$G,$B29) -> 25145072 | M29: =L29/K29-1 -> -0.12354381
B30: 卫衣 | C30: =SUMIFS('男装-品类销售明细'!$I:$I,'男装-品类销售明细'!$C:$C,C$2,'男装-品类销售明细'!$G:$G,$B30) -> 2.168273e+08 | D30: =SUMIFS('男装-品类销售明细'!$I:$I,'男装-品类销售明细'!$C:$C,D$2,'男装-品类销售明细'!$G:$G,$B30) -> 3.8311135e+08 | E30: =SUMIFS('男装-品类销售明细'!$I:$I,'男装-品类销售明细'!$C:$C,E$2,'男装-品类销售明细'!$G:$G,$B30) -> 3.5311167e+08 | F30: =SUMIFS('男装-品类销售明细'!$I:$I,'男装-品类销售明细'!$C:$C,F$2,'男装-品类销售明细'!$G:$G,$B30) -> 3.6011416e+08 | G30: =SUMIFS('男装-品类销售明细'!$I:$I,'男装-品类销售明细'!$C:$C,G$2,'男装-品类销售明细'!$G:$G,$B30) -> 3.3685093e+08 | H30: =SUMIFS('男装-品类销售明细'!$I:$I,'男装-品类销售明细'!$C:$C,H$2,'男装-品类销售明细'!$G:$G,$B30) -> 3.6427562e+08 | I30: =SUMIFS('男装-品类销售明细'!$I:$I,'男装-品类销售明细'!$C:$C,I$2,'男装-品类销售明细'!$G:$G,$B30) -> 1.6497371e+08 | J30: =SUMIFS('男装-品类销售明细'!$I:$I,'男装-品类销售明细'!$C:$C,J$2,'男装-品类销售明细'!$G:$G,$B30) -> 75036934 | ... L30: =SUMIFS('男装-品类销售明细'!$I:$I,'男装-品类销售明细'!$C:$C,L$2,'男装-品类销售明细'!$G:$G,$B30) -> 1.0357297e+08 | M30: =L30/K30-1 -> -0.19158568
B31: 针织衫/毛衣 | C31: =SUMIFS('男装-品类销售明细'!$I:$I,'男装-品类销售明细'!$C:$C,C$2,'男装-品类销售明细'!$G:$G,$B31) -> 2.0159527e+08 | D31: =SUMIFS('男装-品类销售明细'!$I:$I,'男装-品类销售明细'!$C:$C,D$2,'男装-品类销售明细'!$G:$G,$B31) -> 3.4218691e+08 | E31: =SUMIFS('男装-品类销售明细'!$I:$I,'男装-品类销售明细'!$C:$C,E$2,'男装-品类销售明细'!$G:$G,$B31) -> 3.1221953e+08 | F31: =SUMIFS('男装-品类销售明细'!$I:$I,'男装-品类销售明细'!$C:$C,F$2,'男装-品类销售明细'!$G:$G,$B31) -> 3.2206166e+08 | G31: =SUMIFS('男装-品类销售明细'!$I:$I,'男装-品类销售明细'!$C:$C,G$2,'男装-品类销售明细'!$G:$G,$B31) -> 3.2353145e+08 | H31: =SUMIFS('男装-品类销售明细'!$I:$I,'男装-品类销售明细'!$C:$C,H$2,'男装-品类销售明细'!$G:$G,$B31) -> 3.4100804e+08 | I31: =SUMIFS('男装-品类销售明细'!$I:$I,'男装-品类销售明细'!$C:$C,I$2,'男装-品类销售明细'!$G:$G,$B31) -> 1.3926765e+08 | J31: =SUMIFS('男装-品类销售明细'!$I:$I,'男装-品类销售明细'!$C:$C,J$2,'男装-品类销售明细'!$G:$G,$B31) -> 50699283 | ... L31: =SUMIFS('男装-品类销售明细'!$I:$I,'男装-品类销售明细'!$C:$C,L$2,'男装-品类销售明细'!$G:$G,$B31) -> 60287113 | M31: =L31/K31-1 -> -0.054444969
B32: T恤 | C32: =SUMIFS('男装-品类销售明细'!$I:$I,'男装-品类销售明细'!$C:$C,C$2,'男装-品类销售明细'!$G:$G,$B32) -> 1.1907908e+08 | D32: =SUMIFS('男装-品类销售明细'!$I:$I,'男装-品类销售明细'!$C:$C,D$2,'男装-品类销售明细'!$G:$G,$B32) -> 2.2029537e+08 | E32: =SUMIFS('男装-品类销售明细'!$I:$I,'男装-品类销售明细'!$C:$C,E$2,'男装-品类销售明细'!$G:$G,$B32) -> 2.0724218e+08 | F32: =SUMIFS('男装-品类销售明细'!$I:$I,'男装-品类销售明细'!$C:$C,F$2,'男装-品类销售明细'!$G:$G,$B32) -> 1.9407977e+08 | G32: =SUMIFS('男装-品类销售明细'!$I:$I,'男装-品类销售明细'!$C:$C,G$2,'男装-品类销售明细'!$G:$G,$B32) -> 2.0479988e+08 | H32: =SUMIFS('男装-品类销售明细'!$I:$I,'男装-品类销售明细'!$C:$C,H$2,'男装-品类销售明细'!$G:$G,$B32) -> 2.6087323e+08 | I32: =SUMIFS('男装-品类销售明细'!$I:$I,'男装-品类销售明细'!$C:$C,I$2,'男装-品类销售明细'!$G:$G,$B32) -> 1.7004468e+08 | J32: =SUMIFS('男装-品类销售明细'!$I:$I,'男装-品类销售明细'!$C:$C,J$2,'男装-品类销售明细'!$G:$G,$B32) -> 1.6089187e+08 | ... L32: =SUMIFS('男装-品类销售明细'!$I:$I,'男装-品类销售明细'!$C:$C,L$2,'男装-品类销售明细'!$G:$G,$B32) -> 2.6278301e+08 | M32: =L32/K32-1 -> -0.098318623
B33: 皮衣 | C33: =SUMIFS('男装-品类销售明细'!$I:$I,'男装-品类销售明细'!$C:$C,C$2,'男装-品类销售明细'!$G:$G,$B33) -> 1.033758e+08 | D33: =SUMIFS('男装-品类销售明细'!$I:$I,'男装-品类销售明细'!$C:$C,D$2,'男装-品类销售明细'!$G:$G,$B33) -> 1.9609293e+08 | E33: =SUMIFS('男装-品类销售明细'!$I:$I,'男装-品类销售明细'!$C:$C,E$2,'男装-品类销售明细'!$G:$G,$B33) -> 1.784253e+08 | F33: =SUMIFS('男装-品类销售明细'!$I:$I,'男装-品类销售明细'!$C:$C,F$2,'男装-品类销售明细'!$G:$G,$B33) -> 1.8319699e+08 | G33: =SUMIFS('男装-品类销售明细'!$I:$I,'男装-品类销售明细'!$C:$C,G$2,'男装-品类销售明细'!$G:$G,$B33) -> 1.8147596e+08 | H33: =SUMIFS('男装-品类销售明细'!$I:$I,'男装-品类销售明细'!$C:$C,H$2,'男装-品类销售明细'!$G:$G,$B33) -> 1.9470404e+08 | I33: =SUMIFS('男装-品类销售明细'!$I:$I,'男装-品类销售明细'!$C:$C,I$2,'男装-品类销售明细'!$G:$G,$B33) -> 1.1312237e+08 | J33: =SUMIFS('男装-品类销售明细'!$I:$I,'男装-品类销售明细'!$C:$C,J$2,'男装-品类销售明细'!$G:$G,$B33) -> 37343894 | ... L33: =SUMIFS('男装-品类销售明细'!$I:$I,'男装-品类销售明细'!$C:$C,L$2,'男装-品类销售明细'!$G:$G,$B33) -> 65191075 | M33: =L33/K33-1 -> -0.11727719
B34: 毛呢大衣 | C34: =SUMIFS('男装-品类销售明细'!$I:$I,'男装-品类销售明细'!$C:$C,C$2,'男装-品类销售明细'!$G:$G,$B34) -> 75244752 | D34: =SUMIFS('男装-品类销售明细'!$I:$I,'男装-品类销售明细'!$C:$C,D$2,'男装-品类销售明细'!$G:$G,$B34) -> 1.4167981e+08 | E34: =SUMIFS('男装-品类销售明细'!$I:$I,'男装-品类销售明细'!$C:$C,E$2,'男装-品类销售明细'!$G:$G,$B34) -> 1.4984514e+08 | F34: =SUMIFS('男装-品类销售明细'!$I:$I,'男装-品类销售明细'!$C:$C,F$2,'男装-品类销售明细'!$G:$G,$B34) -> 1.4834381e+08 | G34: =SUMIFS('男装-品类销售明细'!$I:$I,'男装-品类销售明细'!$C:$C,G$2,'男装-品类销售明细'!$G:$G,$B34) -> 1.5986455e+08 | H34: =SUMIFS('男装-品类销售明细'!$I:$I,'男装-品类销售明细'!$C:$C,H$2,'男装-品类销售明细'!$G:$G,$B34) -> 1.6141824e+08 | I34: =SUMIFS('男装-品类销售明细'!$I:$I,'男装-品类销售明细'!$C:$C,I$2,'男装-品类销售明细'!$G:$G,$B34) -> 69395326 | J34: =SUMIFS('男装-品类销售明细'!$I:$I,'男装-品类销售明细'!$C:$C,J$2,'男装-品类销售明细'!$G:$G,$B34) -> 11567252 | ... L34: =SUMIFS('男装-品类销售明细'!$I:$I,'男装-品类销售明细'!$C:$C,L$2,'男装-品类销售明细'!$G:$G,$B34) -> 10253206 | M34: =L34/K34-1 -> -0.36301971
B35: 卫裤 | C35: =SUMIFS('男装-品类销售明细'!$I:$I,'男装-品类销售明细'!$C:$C,C$2,'男装-品类销售明细'!$G:$G,$B35) -> 93877704 | D35: =SUMIFS('男装-品类销售明细'!$I:$I,'男装-品类销售明细'!$C:$C,D$2,'男装-品类销售明细'!$G:$G,$B35) -> 1.4847938e+08 | E35: =SUMIFS('男装-品类销售明细'!$I:$I,'男装-品类销售明细'!$C:$C,E$2,'男装-品类销售明细'!$G:$G,$B35) -> 1.2299832e+08 | F35: =SUMIFS('男装-品类销售明细'!$I:$I,'男装-品类销售明细'!$C:$C,F$2,'男装-品类销售明细'!$G:$G,$B35) -> 1.4663449e+08 | G35: =SUMIFS('男装-品类销售明细'!$I:$I,'男装-品类销售明细'!$C:$C,G$2,'男装-品类销售明细'!$G:$G,$B35) -> 1.2755082e+08 | H35: =SUMIFS('男装-品类销售明细'!$I:$I,'男装-品类销售明细'!$C:$C,H$2,'男装-品类销售明细'!$G:$G,$B35) -> 1.2986481e+08 | I35: =SUMIFS('男装-品类销售明细'!$I:$I,'男装-品类销售明细'!$C:$C,I$2,'男装-品类销售明细'!$G:$G,$B35) -> 52329910 | J35: =SUMIFS('男装-品类销售明细'!$I:$I,'男装-品类销售明细'!$C:$C,J$2,'男装-品类销售明细'!$G:$G,$B35) -> 19329588 | ... L35: =SUMIFS('男装-品类销售明细'!$I:$I,'男装-品类销售明细'!$C:$C,L$2,'男装-品类销售明细'!$G:$G,$B35) -> 27203970 | M35: =L35/K35-1 -> -0.10131579
B36: 羊毛衫 | C36: =SUMIFS('男装-品类销售明细'!$I:$I,'男装-品类销售明细'!$C:$C,C$2,'男装-品类销售明细'!$G:$G,$B36) -> 81631018 | D36: =SUMIFS('男装-品类销售明细'!$I:$I,'男装-品类销售明细'!$C:$C,D$2,'男装-品类销售明细'!$G:$G,$B36) -> 1.47308e+08 | E36: =SUMIFS('男装-品类销售明细'!$I:$I,'男装-品类销售明细'!$C:$C,E$2,'男装-品类销售明细'!$G:$G,$B36) -> 1.270362e+08 | F36: =SUMIFS('男装-品类销售明细'!$I:$I,'男装-品类销售明细'!$C:$C,F$2,'男装-品类销售明细'!$G:$G,$B36) -> 1.2021275e+08 | G36: =SUMIFS('男装-品类销售明细'!$I:$I,'男装-品类销售明细'!$C:$C,G$2,'男装-品类销售明细'!$G:$G,$B36) -> 1.120333e+08 | H36: =SUMIFS('男装-品类销售明细'!$I:$I,'男装-品类销售明细'!$C:$C,H$2,'男装-品类销售明细'!$G:$G,$B36) -> 1.058964e+08 | I36: =SUMIFS('男装-品类销售明细'!$I:$I,'男装-品类销售明细'!$C:$C,I$2,'男装-品类销售明细'!$G:$G,$B36) -> 42411542 | J36: =SUMIFS('男装-品类销售明细'!$I:$I,'男装-品类销售明细'!$C:$C,J$2,'男装-品类销售明细'!$G:$G,$B36) -> 8019847.2 | ... L36: =SUMIFS('男装-品类销售明细'!$I:$I,'男装-品类销售明细'!$C:$C,L$2,'男装-品类销售明细'!$G:$G,$B36) -> 15038741 | M36: =L36/K36-1 -> -0.11242228
... B44: POLO衫 | C44: =SUMIFS('男装-品类销售明细'!$I:$I,'男装-品类销售明细'!$C:$C,C$2,'男装-品类销售明细'!$G:$G,$B44) -> 18168048 | D44: =SUMIFS('男装-品类销售明细'!$I:$I,'男装-品类销售明细'!$C:$C,D$2,'男装-品类销售明细'!$G:$G,$B44) -> 29700593 | E44: =SUMIFS('男装-品类销售明细'!$I:$I,'男装-品类销售明细'!$C:$C,E$2,'男装-品类销售明细'!$G:$G,$B44) -> 29706556 | F44: =SUMIFS('男装-品类销售明细'!$I:$I,'男装-品类销售明细'!$C:$C,F$2,'男装-品类销售明细'!$G:$G,$B44) -> 29044564 | G44: =SUMIFS('男装-品类销售明细'!$I:$I,'男装-品类销售明细'!$C:$C,G$2,'男装-品类销售明细'!$G:$G,$B44) -> 30909404 | H44: =SUMIFS('男装-品类销售明细'!$I:$I,'男装-品类销售明细'!$C:$C,H$2,'男装-品类销售明细'!$G:$G,$B44) -> 36815274 | I44: =SUMIFS('男装-品类销售明细'!$I:$I,'男装-品类销售明细'!$C:$C,I$2,'男装-品类销售明细'!$G:$G,$B44) -> 17453939 | J44: =SUMIFS('男装-品类销售明细'!$I:$I,'男装-品类销售明细'!$C:$C,J$2,'男装-品类销售明细'!$G:$G,$B44) -> 30660409 | ... L44: =SUMIFS('男装-品类销售明细'!$I:$I,'男装-品类销售明细'!$C:$C,L$2,'男装-品类销售明细'!$G:$G,$B44) -> 49004631 | M44: =L44/K44-1 -> -0.067177388
A45: 竞品 | C45: W1 | D45: W2 | E45: W3 | F45: W4 | G45: W5 | H45: W6 | I45: W7 | J45: W8 | K45: W9 | L45: W10 | N45: 周关键变化
A46: GXG官方旗舰店 | B46: GMV | G46: 500-750W | H46: 750-1000W | I46: 250-500W | J46: 10-25W | K46: 250-500W | L46: 250-500W | N46: 1、上周主打裤装、夹克、卫衣，其中牛仔裤G26D052031、G25D052118、G26D021062表现好，男装店基本没库存；
A47: 太平鸟男装官方旗舰店 | B47: GMV | G47: 500-750W | H47: 500-750W | I47: 100-250W | J47: 7.5-10W | K47: 75-100W | L47: 100-250W | N47: 1、上一周TOP单品均为满印/满提花元素外套；

Sheet GXG-日报
A1: 品牌 | B1: 日期 | C1: 年份 | D1: 月份 | E1: 周数 | F1: GMV | G1: 成交退款金额(退款时间) | H1: NET | I1: 商品卡GMV | J1: 直播GMV | K1: 投放消耗金额 | L1: ROI
A2: GXG | B2: 46023 | C2: =TEXT(YEAR(B2),"0")&"年" -> 2026年 | D2: =TEXT(MONTH(B2),"0")&"月" -> 1月 | E2: ="W"&TEXT(WEEKNUM(B2,2),"0") -> W1 | F2: 473933 | G2: 329167.89 | H2: =F2-G2 -> 144765.11 | I2: 53339 | J2: 413939 | K2: 15020.82 | L2: =J2/K2 -> 27.557683
A3: GXG | B3: 46024 | C3: =TEXT(YEAR(B3),"0")&"年" -> 2026年 | D3: =TEXT(MONTH(B3),"0")&"月" -> 1月 | E3: ="W"&TEXT(WEEKNUM(B3,2),"0") -> W1 | F3: 444251 | G3: 279102.56 | H3: =F3-G3 -> 165148.44 | I3: 50496 | J3: 385950 | K3: 14622.86 | L3: =J3/K3 -> 26.393606
A4: GXG | B4: 46025 | C4: =TEXT(YEAR(B4),"0")&"年" -> 2026年 | D4: =TEXT(MONTH(B4),"0")&"月" -> 1月 | E4: ="W"&TEXT(WEEKNUM(B4,2),"0") -> W1 | F4: 674234.99 | G4: 346786.75 | H4: =F4-G4 -> 327448.24 | I4: 72964 | J4: 591359.99 | K4: 22240.9 | L4: =J4/K4 -> 26.588852
A5: GXG | B5: 46026 | C5: =TEXT(YEAR(B5),"0")&"年" -> 2026年 | D5: =TEXT(MONTH(B5),"0")&"月" -> 1月 | E5: ="W"&TEXT(WEEKNUM(B5,2),"0") -> W1 | F5: 862390.42 | G5: 363357.27 | H5: =F5-G5 -> 499033.15 | I5: 72998.42 | J5: 772244 | K5: 29517.73 | L5: =J5/K5 -> 26.162039
A6: GXG | B6: 46027 | C6: =TEXT(YEAR(B6),"0")&"年" -> 2026年 | D6: =TEXT(MONTH(B6),"0")&"月" -> 1月 | E6: ="W"&TEXT(WEEKNUM(B6,2),"0") -> W2 | F6: 396291.82 | G6: 300916.79 | H6: =F6-G6 -> 95375.03 | I6: 63297.64 | J6: 322043.24 | K6: 11563.43 | L6: =J6/K6 -> 27.850148
A7: GXG | B7: 46028 | C7: =TEXT(YEAR(B7),"0")&"年" -> 2026年 | D7: =TEXT(MONTH(B7),"0")&"月" -> 1月 | E7: ="W"&TEXT(WEEKNUM(B7,2),"0") -> W2 | F7: 491573.49 | G7: 330114.1 | H7: =F7-G7 -> 161459.39 | I7: 56931.28 | J7: 421440.27 | K7: 15404.97 | L7: =J7/K7 -> 27.357422
A8: GXG | B8: 46029 | C8: =TEXT(YEAR(B8),"0")&"年" -> 2026年 | D8: =TEXT(MONTH(B8),"0")&"月" -> 1月 | E8: ="W"&TEXT(WEEKNUM(B8,2),"0") -> W2 | F8: 1055153.4 | G8: 435055.56 | H8: =F8-G8 -> 620097.79 | I8: 74211.01 | J8: 969128.7 | K8: 37826.72 | L8: =J8/K8 -> 25.620215
A9: GXG | B9: 46030 | C9: =TEXT(YEAR(B9),"0")&"年" -> 2026年 | D9: =TEXT(MONTH(B9),"0")&"月" -> 1月 | E9: ="W"&TEXT(WEEKNUM(B9,2),"0") -> W2 | F9: 690608.71 | G9: 343465.27 | H9: =F9-G9 -> 347143.44 | I9: 57300.58 | J9: 623972 | K9: 22188.28 | L9: =J9/K9 -> 28.121693
A10: GXG | B10: 46031 | C10: =TEXT(YEAR(B10),"0")&"年" -> 2026年 | D10: =TEXT(MONTH(B10),"0")&"月" -> 1月 | E10: ="W"&TEXT(WEEKNUM(B10,2),"0") -> W2 | F10: 647734.73 | G10: 350854.74 | H10: =F10-G10 -> 296879.99 | I10: 58141.46 | J10: 579154.99 | K10: 20245.73 | L10: =J10/K10 -> 28.606278
A11: GXG | B11: 46032 | C11: =TEXT(YEAR(B11),"0")&"年" -> 2026年 | D11: =TEXT(MONTH(B11),"0")&"月" -> 1月 | E11: ="W"&TEXT(WEEKNUM(B11,2),"0") -> W2 | F11: 640428.84 | G11: 400050.86 | H11: =F11-G11 -> 240377.98 | I11: 49943.2 | J11: 581678.64 | K11: 20841.12 | L11: =J11/K11 -> 27.910143
A12: GXG | B12: 46033 | C12: =TEXT(YEAR(B12),"0")&"年" -> 2026年 | D12: =TEXT(MONTH(B12),"0")&"月" -> 1月 | E12: ="W"&TEXT(WEEKNUM(B12,2),"0") -> W2 | F12: 550331.18 | G12: 348699.63 | H12: =F12-G12 -> 201631.55 | I12: 59266.18 | J12: 483041 | K12: 17587.31 | L12: =J12/K12 -> 27.465314
A13: GXG | B13: 46034 | C13: =TEXT(YEAR(B13),"0")&"年" -> 2026年 | D13: =TEXT(MONTH(B13),"0")&"月" -> 1月 | E13: ="W"&TEXT(WEEKNUM(B13,2),"0") -> W3 | F13: 449261 | G13: 344754.84 | H13: =F13-G13 -> 104506.16 | I13: 51530 | J13: 389110 | K13: 14151.91 | L13: =J13/K13 -> 27.495229
... A20: GXG | B20: 46041 | C20: =TEXT(YEAR(B20),"0")&"年" -> 2026年 | D20: =TEXT(MONTH(B20),"0")&"月" -> 1月 | E20: ="W"&TEXT(WEEKNUM(B20,2),"0") -> W4 | F20: 388005 | G20: 249460.1 | H20: =F20-G20 -> 138544.9 | I20: 85461 | J20: 295683 | K20: 9163.25 | L20: =J20/K20 -> 32.268355
